Workbook

Sheet 资产负债表
A1: 资产负债表
A2: 编制单位：上海佰茶跳动科技有限公司 | D2: 截止日：2026.05.31 | F2: 单位：元
A3: 项目 | B3: 期末余额 | C3: 年初余额 | D3: 项目 | E3: 期末余额 | F3: 年初余额
A4: 流动资产： | B4: 0 | C4: 0 | D4: 流动负债： | E4: 0 | F4: 0
A5: 货币资金 | B5: 1414786.9 | C5: 3615121.2 | D5: 短期借款 | E5: 0 | F5: 0
A6: 交易性金融资产 | B6: 0 | C6: 0 | D6: 交易性金融负债 | E6: 0 | F6: 0
A7: 应收票据 | B7: 0 | C7: 0 | D7: 应付票据 | E7: 0 | F7: 0
A8: 应收账款 | B8: 908206.67 | C8: 55611.33 | D8: 应付账款 | E8: 1260096.1 | F8: 1197402.1
A9: 应收款项融资 | B9: 0 | C9: 0 | D9: 预收款项 | E9: 12790.19 | F9: 20191.36
A10: 预付款项 | B10: 0 | C10: 241200 | D10: 合同负债 | E10: 0 | F10: 0
A11: 其他应收款 | B11: 81886.46 | C11: 101587.28 | D11: 应付职工薪酬 | E11: 137555.76 | F11: 76142.06
A12: 其中：应收利息 | B12: 0 | C12: 0 | D12: 应交税费 | E12: -73098.3 | F12: 72075.4
A13: 应收股利 | B13: 0 | C13: 0 | D13: 其他应付款 | E13: 709403.01 | F13: 224895.94
A14: 存货 | B14: 2346633.1 | C14: 1321803 | D14: 其中：应付利息 | E14: 0 | F14: 0
A15: 合同资产 | B15: 0 | C15: 0 | D15: 应付股利 | E15: 0 | F15: 0
... A17: 其他流动资产 | B17: 0 | C17: 0 | D17: 其他流动负债 | E17: 0 | F17: 0
A18: 流动资产合计 | B18: =SUM(B4:B17)-B12 -> 4751513.2 | C18: =SUM(C4:C17)-C12 -> 5335322.9 | D18: 流动负债合计 | E18: =SUM(E4:E17)-E14 -> 2046746.8 | F18: =SUM(F4:F17)-F14 -> 1590706.8
A19: 非流动资产： | B19: 0 | C19: 0 | D19: 非流动负债： | E19: 0 | F19: 0
A20: 可供出售金融资产 | B20: 0 | C20: 0 | D20: 长期借款 | E20: 0 | F20: 0
A21: 持有至到期投资 | B21: 0 | C21: 0 | D21: 应付债券 | E21: 0 | F21: 0
A22: 长期应收款 | B22: 0 | C22: 0 | D22: 租赁负债 | E22: 0 | F22: 0
A23: 长期股权投资 | B23: 0 | C23: 0 | D23: 长期应付款 | E23: 0 | F23: 0
A24: 投资性房地产 | B24: 0 | C24: 0 | D24: 长期应付职工薪酬 | E24: 0 | F24: 0
A25: 固定资产 | B25: 0 | C25: 0 | D25: 预计负债 | E25: 0 | F25: 0
A26: 在建工程 | B26: 0 | C26: 0 | D26: 递延收益 | E26: 0 | F26: 0
A27: 使用权资产 | B27: 0 | C27: 0 | D27: 递延所得税负债 | E27: 0 | F27: 0
A28: 无形资产 | B28: 0 | C28: 0 | D28: 其他非流动负债 | E28: 0 | F28: 0
A29: 开发支出 | B29: 0 | C29: 0 | D29: 非流动负债合计 | E29: =SUM(E19:E28) -> 0 | F29: =SUM(F19:F28) -> 0
A30: 商誉 | B30: 0 | C30: 0 | D30: 负债合计 | E30: =E29+E18 -> 2046746.8 | F30: =F29+F18 -> 1590706.8
A31: 长期待摊费用 | B31: 0 | C31: 0 | D31: 股东权益： | E31: 0 | F31: 0
A32: 递延所得税资产 | B32: 0 | C32: 0 | D32: 股本 | E32: 5000000 | F32: 5000000
A33: 其他非流动资产 | B33: 0 | C33: 0 | D33: 资本公积 | E33: 0 | F33: 0
A34: 非流动资产合计 | B34: =SUM(B19:B33) -> 0 | C34: 0 | D34: 减：库存股 | E34: 0 | F34: 0
B35: 0 | C35: 0 | D35: 其他综合收益 | E35: 0 | F35: 0
B36: 0 | C36: 0 | D36: 盈余公积 | E36: 0 | F36: 0
B37: 0 | C37: 0 | D37: 未分配利润 | E37: -2295233.6 | F37: -1255383.9
B38: 0 | C38: 0 | D38: 归属于母公司股东权益合计 | E38: 0 | F38: 0
B39: 0 | C39: 0 | D39: 少数股东权益 | E39: 0 | F39: 0
B40: 0 | C40: 0 | D40: 股东权益合计 | E40: =E32+E33-E34+E35+E36+E37 -> 2704766.4 | F40: =F32+F33-F34+F35+F36+F37 -> 3744616
A41: 资产总计 | B41: =B34+B18 -> 4751513.2 | C41: =C34+C18 -> 5335322.9 | D41: 负债和股东权益总计 | E41: =E40+E30 -> 4751513.2 | F41: =F40+F30 -> 5335322.9
...

Sheet 利润表
A1: 利润表
A2: =资产负债表!A2 -> 编制单位：上海佰茶跳动科技有限公司 | G2: 单位：元
A3: 项目 | B3: 1月份 | C3: 2月份 | D3: 3月份 | E3: 4月份 | F3: 5月份 | G3: 累计
A4: 一、营业总收入 | B4: 1351569.1 | C4: 1427666.1 | D4: 1169553.3 | E4: 876722.98 | F4: 1587416.8 | G4: 6412928.3
A5: 其中:营业收入 | B5: 1351569.1 | C5: 1427666.1 | D5: 1169553.3 | E5: 876722.98 | F5: 1587416.8 | G5: 6412928.3
A6: 二、营业总成本 | B6: 1585828.5 | C6: 1481607.5 | D6: 1547738 | E6: 1145871.6 | F6: 1691767.1 | G6: 7452812.7
A7: 其中：营业成本 | B7: 605760.8 | C7: 668063.05 | D7: 667605.55 | E7: 497465.29 | F7: 1036063.7 | G7: 3474958.3
A8: 税金及附加 | B8: 6142.97 | C8: 6195.63 | D8: 3609.92 | E8: -439.47 | F8: 0 | G8: 15509.05
A9: 销售费用 | B9: 973805.6 | C9: 807236.75 | D9: 876775.3 | E9: 648702.18 | F9: 655609.19 | G9: 3962129
A10: 管理费用 | B10: 0 | C10: 0 | D10: 0 | E10: 0 | F10: 0 | G10: 0
A11: 研发费用 | B11: 0 | C11: 0 | D11: 0 | E11: 0 | F11: 0 | G11: 0
A12: 财务费用 | B12: 119.12 | C12: 112.05 | D12: -252.73 | E12: 143.58 | F12: 94.22 | G12: 216.24
A13: 其中：利息费用 | B13: 0 | C13: 0 | D13: 0 | E13: 0 | F13: 0 | G13: 0
A14: 利息收入 | B14: 0 | C14: 0 | D14: 0 | E14: 0 | F14: 0 | G14: 0
A15: 加：其他收益 | B15: 0 | C15: 0 | D15: 34.68 | E15: 0 | F15: 0 | G15: 34.68
... A27: 五、净利润（净亏损以“－”号填列） | B27: -234259.35 | C27: -53941.41 | D27: -378150.03 | E27: -269148.6 | F27: -104350.28 | G27: -1039849.7

Sheet 现金流量表
A1: 现金流量表
A2: =资产负债表!A2 -> 编制单位：上海佰茶跳动科技有限公司 | G2: 单位：元
A3: 一、经营活动产生的现金流量： | B3: 1月份 | C3: 2月份 | D3: 3月份 | E3: 4月份 | F3: 5月份 | G3: 累计
A4: 销售商品、提供劳务收到的现金 | B4: 1274434.7 | C4: 1333212.2 | D4: 1020203.9 | E4: 711025.47 | F4: 1046680.6 | G4: =B4+C4+D4+E4+F4 -> 5385556.8
A5: 收到的税费返还 | B5: 0 | C5: 0 | D5: 0 | E5: 0 | F5: 0 | G5: =B5+C5+D5+E5+F5 -> 0
A6: 收到其他与经营活动有关的现金 | B6: 53266.5 | C6: 0.65 | D6: 392.72 | E6: 670498.25 | F6: 0 | G6: =B6+C6+D6+E6+F6 -> 724158.12
A7: 经营活动现金流入小计 | B7: =SUM(B4:B6) -> 1327701.2 | C7: =SUM(C4:C6) -> 1333212.8 | D7: =SUM(D4:D6) -> 1020596.6 | E7: =SUM(E4:E6) -> 1381523.7 | F7: =SUM(F4:F6) -> 1046680.6 | G7: =SUM(G4:G6) -> 6109715
A8: 购买商品、接受劳务支付的现金 | B8: 1208707 | C8: 1352906.3 | D8: 1405925.2 | E8: 1660774.3 | F8: 1778040.8 | G8: =B8+C8+D8+E8+F8 -> 7406353.6
A9: 支付给职工以及为职工支付的现金 | B9: 76247.13 | C9: 99930.68 | D9: 94379.87 | E9: 112451.12 | F9: 117913.87 | G9: =B9+C9+D9+E9+F9 -> 500922.67
A10: 支付的各项税费 | B10: 72743.1 | C10: 79724.35 | D10: 121710.89 | E10: 83814.23 | F10: 0 | G10: =B10+C10+D10+E10+F10 -> 357992.57
A11: 支付其他与经营活动有关的现金 | B11: 14498.89 | C11: 112.7 | D11: 103.23 | E11: 28706.37 | F11: 1359.22 | G11: =B11+C11+D11+E11+F11 -> 44780.41
A12: 经营活动现金流出小计 | B12: =SUM(B8:B11) -> 1372196.1 | C12: =SUM(C8:C11) -> 1532674 | D12: =SUM(D8:D11) -> 1622119.2 | E12: =SUM(E8:E11) -> 1885746 | F12: =SUM(F8:F11) -> 1897313.9 | G12: =SUM(G8:G11) -> 8310049.2
A13: 经营活动产生的现金流量净额 | B13: =B7-B12 -> -44494.94 | C13: =C7-C12 -> -199461.18 | D13: =D7-D12 -> -601522.62 | E13: =E7-E12 -> -504222.27 | F13: =F7-F12 -> -850633.27 | G13: =G7-G12 -> -2200334.3
A14: 二、投资活动产生的现金流量： | G14: =B14+C14+D14+E14+F14 -> 0
A15: 收回投资收到的现金 | G15: =B15+C15+D15+E15+F15 -> 0
A16: 取得投资收益收到的现金 | G16: =B16+C16+D16+E16+F16 -> 0
A17: 处置固定资产、无形资产和其他长期资产收回的现金净额 | G17: =B17+C17+D17+E17+F17 -> 0
A18: 处置子公司及其他营业单位收到的现金净额 | G18: =B18+C18+D18+E18+F18 -> 0
A19: 收到其他与投资活动有关的现金 | G19: =B19+C19+D19+E19+F19 -> 0
A20: 投资活动现金流入小计 | B20: =SUM(B15:B19) -> 0 | C20: =SUM(C15:C19) -> 0 | D20: =SUM(D15:D19) -> 0 | E20: =SUM(E15:E19) -> 0 | F20: =SUM(F15:F19) -> 0 | G20: =SUM(G15:G19) -> 0
A21: 购建固定资产、无形资产和其他长期资产支付的现金 | G21: =B21+C21+D21+E21+F21 -> 0
A22: 投资支付的现金 | G22: =B22+C22+D22+E22+F22 -> 0
A23: 质押贷款净增加额 | G23: =B23+C23+D23+E23+F23 -> 0
A24: 取得子公司及其他营业单位支付的现金净额 | G24: =B24+C24+D24+E24+F24 -> 0
A25: 支付其他与投资活动有关的现金 | G25: =B25+C25+D25+E25+F25 -> 0
A26: 投资活动现金流出小计 | B26: =SUM(B21:B25) -> 0 | C26: =SUM(C21:C25) -> 0 | D26: =SUM(D21:D25) -> 0 | E26: =SUM(E21:E25) -> 0 | F26: =SUM(F21:F25) -> 0 | G26: =SUM(G21:G25) -> 0
A27: 投资活动产生的现金流量净额 | B27: =B20-B26 -> 0 | C27: =C20-C26 -> 0 | D27: =D20-D26 -> 0 | E27: =E20-E26 -> 0 | F27: =F20-F26 -> 0 | G27: =G20-G26 -> 0
A28: 三、筹资活动产生的现金流量： | G28: =B28+C28+D28+E28+F28 -> 0
A29: 吸收投资收到的现金 | G29: =B29+C29+D29+E29+F29 -> 0
A30: 取得借款所收到的现金 | G30: =B30+C30+D30+E30+F30 -> 0
A31: 发行债券收到的现金 | G31: =B31+C31+D31+E31+F31 -> 0
A32: 收到其他与筹资活动有关的现金 | G32: =B32+C32+D32+E32+F32 -> 0
A33: 筹资活动现金流入小计 | B33: =SUM(B29:B32) -> 0 | C33: =SUM(C29:C32) -> 0 | D33: =SUM(D29:D32) -> 0 | E33: =SUM(E29:E32) -> 0 | F33: =SUM(F29:F32) -> 0 | G33: =SUM(G29:G32) -> 0
A34: 偿还债务所支付的现金 | G34: =B34+C34+D34+E34+F34 -> 0
A35: 分配股利、利润或偿付利息所支付的现金 | G35: =B35+C35+D35+E35+F35 -> 0
A36: 支付其他与筹资活动有关的现金 | G36: =B36+C36+D36+E36+F36 -> 0
A37: 筹资活动现金流出小计 | B37: =SUM(B34:B36) -> 0 | C37: =SUM(C34:C36) -> 0 | D37: =SUM(D34:D36) -> 0 | E37: =SUM(E34:E36) -> 0 | F37: =SUM(F34:F36) -> 0 | G37: =SUM(G34:G36) -> 0
A38: 筹资活动产生的现金流量净额 | B38: =B33-B37 -> 0 | C38: =C33-C37 -> 0 | D38: =D33-D37 -> 0 | E38: =E33-E37 -> 0 | F38: =F33-F37 -> 0 | G38: =G33-G37 -> 0
A39: 四、汇率变动对现金及现金等价物的影响 | G39: =B39+C39+D39+E39+F39 -> 0
A40: 五、现金及现金等价物净增加额 | B40: =B38+B39+B27+B13 -> -44494.94 | C40: =C38+C39+C27+C13 -> -199461.18 | D40: =D38+D39+D27+D13 -> -601522.62 | E40: =E38+E39+E27+E13 -> -504222.27 | F40: =F38+F39+F27+F13 -> -850633.27 | G40: =G38+G39+G27+G13 -> -2200334.3
...

Sheet 科余表
A1: 公司代码 | B1: 公司代码描述 | C1: 利润中心 | D1: 利润中心描述 | E1: 科目 | F1: 科目描述 | G1: 客户编号 | H1: 客户描述 | I1: 供应商编码 | J1: 供应商描述 | K1: 期初金额 | L1: 本期借方 | M1: 本期贷方 | N1: 期末金额 | O1: 科目
A2: 2240 | B2: 上海佰茶跳动科技有限公司 | C2: 35I2190001 | D2: 佰茶绿雪芽线下分销 | E2: 1122010100 | F2: 应收账款:商品销售 | G2: 0000101388 | H2: 广州市简健农业科技有限公司-佰茶 | K2: 0 | L2: 255484.6 | M2: -255484.6 | N2: 0 | O2: 应收账款
A3: 2240 | B3: 上海佰茶跳动科技有限公司 | C3: 35I2030001 | D3: 佰茶绿雪芽抖音旗舰店 | E3: 1122010100 | F3: 应收账款:商品销售 | G3: 0000101225 | H3: 上海璞康实业有限公司-内部往来 | K3: 0 | L3: 2107.35 | M3: 0 | N3: 2107.35 | O3: 应收账款
A4: 2240 | B4: 上海佰茶跳动科技有限公司 | C4: 9900000001 | D4: 内部往来（采销业务&集团共用） | E4: 1122010100 | F4: 应收账款:商品销售 | G4: 0000602556 | H4: 上海佰茶跳动科技有限公司-内部往来 | K4: 0 | L4: 2870 | M4: -2870 | N4: 0 | O4: 应收账款
A5: 2240 | B5: 上海佰茶跳动科技有限公司 | C5: 35I2190001 | D5: 佰茶绿雪芽线下分销 | E5: 1122010100 | F5: 应收账款:商品销售 | G5: 0000101268 | H5: 汇嘉信（上海）贸易发展有限公司-绿雪芽项目 | K5: 0 | L5: 16266.6 | M5: -16266.6 | N5: 0 | O5: 应收账款
A6: 2240 | B6: 上海佰茶跳动科技有限公司 | C6: 35I2140001 | D6: 佰茶绿雪芽天猫旗舰店 | E6: 1122010100 | F6: 应收账款:商品销售 | G6: 0000101225 | H6: 上海璞康实业有限公司-内部往来 | K6: 2735 | L6: 131244.45 | M6: -133979.45 | N6: 0 | O6: 应收账款
A7: 2240 | B7: 上海佰茶跳动科技有限公司 | C7: 35I2190001 | D7: 佰茶绿雪芽线下分销 | E7: 1122010100 | F7: 应收账款:商品销售 | G7: A0001 | H7: 零星客户 | K7: 0 | L7: 101322.85 | M7: -101322.85 | N7: 0 | O7: 应收账款
A8: 2240 | B8: 上海佰茶跳动科技有限公司 | C8: 35I2190001 | D8: 佰茶绿雪芽线下分销 | E8: 1122010100 | F8: 应收账款:商品销售 | G8: 0000101225 | H8: 上海璞康实业有限公司-内部往来 | K8: -1288.1 | L8: 143086.05 | M8: -136815.15 | N8: 4982.8 | O8: 应收账款
A9: 2240 | B9: 上海佰茶跳动科技有限公司 | C9: 35I2190001 | D9: 佰茶绿雪芽线下分销 | E9: 1122010100 | F9: 应收账款:商品销售 | G9: 0000100624 | H9: 汇嘉信(上海)贸易发展有限公司 | K9: -16266.6 | L9: 16266.6 | M9: 0 | N9: 0 | O9: 应收账款
A10: 2240 | B10: 上海佰茶跳动科技有限公司 | C10: 35I2140001 | D10: 佰茶绿雪芽天猫旗舰店 | E10: 1122010100 | F10: 应收账款:商品销售 | G10: A0001 | H10: 零星客户 | K10: 0 | L10: 40558.65 | M10: -40558.65 | N10: 0 | O10: 应收账款
A11: 2240 | B11: 上海佰茶跳动科技有限公司 | C11: 35I2140001 | D11: 佰茶绿雪芽天猫旗舰店 | E11: 1122010101 | F11: 应收账款:B2C平台 | G11: 0000200392 | H11: 绿雪芽-天猫旗舰店-佰茶 | K11: -3924.76 | L11: 2821170.1 | M11: -2817235.3 | N11: 10.01 | O11: 应收账款
A12: 2240 | B12: 上海佰茶跳动科技有限公司 | C12: 35I2060001 | D12: 佰茶绿雪芽京东POP旗舰店 | E12: 1122010101 | F12: 应收账款:B2C平台 | G12: 0000200384 | H12: 绿雪芽-京东POP旗舰店-佰茶 | K12: 0 | L12: 246250.79 | M12: -246250.79 | N12: 0 | O12: 应收账款
A13: 2240 | B13: 上海佰茶跳动科技有限公司 | C13: 9900000001 | D13: 内部往来（采销业务&集团共用） | E13: 1122020100 | F13: 应收账款:集团商品销售 | G13: 0000002100 | H13: 上海璞睿供应链管理服务有限公司 | K13: 41504.22 | L13: 1737802.5 | M13: -878200.24 | N13: 901106.51 | O13: 应收账款
... A18: 2240 | B18: 上海佰茶跳动科技有限公司 | C18: 35I2140001 | D18: 佰茶绿雪芽天猫旗舰店 | E18: 1122020200 | F18: 应收账款:集团服务 | G18: 0000002250 | H18: 上海璞樾数据科技有限公司 | K18: 10000 | L18: 10000 | M18: -20000 | N18: 0 | O18: 应收账款
A19: 2240 | B19: 上海佰茶跳动科技有限公司 | C19: 35I2140001 | D19: 佰茶绿雪芽天猫旗舰店 | E19: 1123020700 | F19: 预付账款:预付费用:直通车 | I19: 0000600144 | J19: 淘宝（中国）软件有限公司 | K19: 204000 | L19: 70000 | M19: -274000 | N19: 0 | O19: 预付款项
A20: 2240 | B20: 上海佰茶跳动科技有限公司 | C20: 35I2060001 | D20: 佰茶绿雪芽京东POP旗舰店 | E20: 1123021000 | F20: 预付账款:预付费用:京准通 | I20: 0000400617 | J20: 广西京东星辰电子商务有限公司 | K20: 36000 | L20: 0 | M20: -36000 | N20: 0 | O20: 预付款项
A21: 2240 | B21: 上海佰茶跳动科技有限公司 | C21: 35I2060001 | D21: 佰茶绿雪芽京东POP旗舰店 | E21: 1221010000 | F21: 其他应收款:保证金/押金 | G21: 0000200384 | H21: 绿雪芽-京东POP旗舰店-佰茶 | K21: 500 | L21: 4500 | M21: 0 | N21: 5000 | O21: 其他应收款
A22: 2240 | B22: 上海佰茶跳动科技有限公司 | C22: 35I2140001 | D22: 佰茶绿雪芽天猫旗舰店 | E22: 1221010000 | F22: 其他应收款:保证金/押金 | G22: 0000200392 | H22: 绿雪芽-天猫旗舰店-佰茶 | K22: 50000 | L22: 0 | M22: 0 | N22: 50000 | O22: 其他应收款
A23: 2240 | B23: 上海佰茶跳动科技有限公司 | C23: 35I2030001 | D23: 佰茶绿雪芽抖音旗舰店 | E23: 1221010000 | F23: 其他应收款:保证金/押金 | G23: 0000601052 | H23: 北京有竹居网络技术有限公司 | K23: 500 | L23: 0 | M23: 0 | N23: 500 | O23: 其他应收款
A24: 2240 | B24: 上海佰茶跳动科技有限公司 | C24: 35I2200001 | D24: 佰茶绿雪芽小红书旗舰店 | E24: 1221010000 | F24: 其他应收款:保证金/押金 | G24: 0000602154 | H24: 优穗信息科技(上海)有限公司 | K24: 10000 | L24: 0 | M24: 0 | N24: 10000 | O24: 其他应收款
A25: 2240 | B25: 上海佰茶跳动科技有限公司 | C25: 46I2160001 | D25: 佰茶绿雪芽微信小店 | E25: 1221010000 | F25: 其他应收款:保证金/押金 | G25: 0000200414 | H25: 绿雪芽-微信小店-佰茶 | K25: 2000 | L25: 0 | M25: 0 | N25: 2000 | O25: 其他应收款
A26: 2240 | B26: 上海佰茶跳动科技有限公司 | C26: 35I2030001 | D26: 佰茶绿雪芽抖音旗舰店 | E26: 1221999909 | F26: 其他应收款:B2B | G26: 0000602387 | H26: 杭州照茗文化传播有限公司 | K26: 0 | L26: 2838.19 | M26: 0 | N26: 2838.19 | O26: 其他应收款
A27: 2240 | B27: 上海佰茶跳动科技有限公司 | C27: 35I2030001 | D27: 佰茶绿雪芽抖音旗舰店 | E27: 1221999909 | F27: 其他应收款:B2B | G27: 0000601940 | H27: 成都声云文化传播有限公司 | K27: 0 | L27: 9369.77 | M27: -9369.77 | N27: 0 | O27: 其他应收款
A28: 2240 | B28: 上海佰茶跳动科技有限公司 | C28: 35I2140001 | D28: 佰茶绿雪芽天猫旗舰店 | E28: 1221999909 | F28: 其他应收款:B2B | G28: 0000602387 | H28: 杭州照茗文化传播有限公司 | K28: 0 | L28: 3794.12 | M28: -3794.12 | N28: 0 | O28: 其他应收款
A29: 2240 | B29: 上海佰茶跳动科技有限公司 | C29: 46I2070001 | D29: 佰茶绿雪芽京东自营店 | E29: 1221999909 | F29: 其他应收款:B2B | G29: A0001 | H29: 零星客户 | K29: 0 | L29: 28.14 | M29: -27.05 | N29: 1.09 | O29: 其他应收款
A30: 2240 | B30: 上海佰茶跳动科技有限公司 | C30: 35I2030001 | D30: 佰茶绿雪芽抖音旗舰店 | E30: 1221999909 | F30: 其他应收款:B2B | G30: A0001 | H30: 零星客户 | K30: 566.04 | L30: 6509.46 | M30: -6226.44 | N30: 849.06 | O30: 其他应收款
A31: 2240 | B31: 上海佰茶跳动科技有限公司 | C31: 46I2ZZ0001 | D31: 佰茶绿雪芽本地生活分销 | E31: 1221999909 | F31: 其他应收款:B2B | G31: A0001 | H31: 零星客户 | K31: 2037.74 | L31: 5094.35 | M31: -4075.48 | N31: 3056.61 | O31: 其他应收款
A32: 2240 | B32: 上海佰茶跳动科技有限公司 | C32: 35I2140001 | D32: 佰茶绿雪芽天猫旗舰店 | E32: 1221999909 | F32: 其他应收款:B2B | G32: A0001 | H32: 零星客户 | K32: 35983.5 | L32: 34720.77 | M32: -63062.76 | N32: 7641.51 | O32: 其他应收款
A33: 2240 | B33: 上海佰茶跳动科技有限公司 | C33: 35I2190001 | D33: 佰茶绿雪芽线下分销 | E33: 2202010100 | F33: 应付账款:商品采购 | I33: 0000602557 | J33: 上海璞樾数据科技有限公司-内部往来 | K33: 0 | L33: 1670 | M33: -1670 | N33: 0 | O33: 应付账款
A34: 2240 | B34: 上海佰茶跳动科技有限公司 | C34: 35I2030001 | D34: 佰茶绿雪芽抖音旗舰店 | E34: 2202010100 | F34: 应付账款:商品采购 | I34: 0000602574 | J34: 福建省天湖茶业有限公司 | K34: 0 | L34: 48084.93 | M34: -48084.93 | N34: 0 | O34: 应付账款
A35: 2240 | B35: 上海佰茶跳动科技有限公司 | C35: 35I2140001 | D35: 佰茶绿雪芽天猫旗舰店 | E35: 2202010100 | F35: 应付账款:商品采购 | I35: 0000602452 | J35: 福建太姥山名茶有限公司 | K35: 0 | L35: 3000 | M35: -3000 | N35: 0 | O35: 应付账款
A36: 2240 | B36: 上海佰茶跳动科技有限公司 | C36: 35I2190001 | D36: 佰茶绿雪芽线下分销 | E36: 2202010100 | F36: 应付账款:商品采购 | I36: 0000602452 | J36: 福建太姥山名茶有限公司 | K36: 0 | L36: 3000 | M36: -3000 | N36: 0 | O36: 应付账款
A37: 2240 | B37: 上海佰茶跳动科技有限公司 | C37: 35I2190001 | D37: 佰茶绿雪芽线下分销 | E37: 2202010100 | F37: 应付账款:商品采购 | I37: A0001 | J37: 零星客户 | K37: 1200 | L37: 470 | M37: -1670 | N37: 0 | O37: 应付账款
A38: 2240 | B38: 上海佰茶跳动科技有限公司 | C38: 35I2140001 | D38: 佰茶绿雪芽天猫旗舰店 | E38: 2202010100 | F38: 应付账款:商品采购 | I38: 0000602295 | J38: 福建绿雪芽茶业有限公司 | K38: 428652 | L38: 5139238.6 | M38: -4033365 | N38: 1534525.6 | O38: 应付账款
A39: 2240 | B39: 上海佰茶跳动科技有限公司 | C39: 35I2140001 | D39: 佰茶绿雪芽天猫旗舰店 | E39: 2202010101 | F39: 应付账款-商品采购-暂估应付款 | I39: 0000602295 | J39: 福建绿雪芽茶业有限公司 | K39: -924033.89 | L39: 3177784.7 | M39: -4421691.5 | N39: -2167940.7 | O39: 应付账款
A40: 2240 | B40: 上海佰茶跳动科技有限公司 | C40: 9900000001 | D40: 内部往来（采销业务&集团共用） | E40: 2202010101 | F40: 应付账款-商品采购-暂估应付款 | K40: 0 | L40: 76320.9 | M40: -76320.9 | N40: 0 | O40: 应付账款
A41: 2240 | B41: 上海佰茶跳动科技有限公司 | C41: 35I2190001 | D41: 佰茶绿雪芽线下分销 | E41: 2202010101 | F41: 应付账款-商品采购-暂估应付款 | I41: 0000602557 | J41: 上海璞樾数据科技有限公司-内部往来 | K41: -1061.95 | L41: 1477.88 | M41: -415.93 | N41: 0 | O41: 应付账款
A42: 2240 | B42: 上海佰茶跳动科技有限公司 | C42: 35I2060001 | D42: 佰茶绿雪芽京东POP旗舰店 | E42: 2202010101 | F42: 应付账款-商品采购-暂估应付款 | I42: 0000602295 | J42: 福建绿雪芽茶业有限公司 | K42: -18349.56 | L42: 18349.56 | M42: 0 | N42: 0 | O42: 应付账款
A43: 2240 | B43: 上海佰茶跳动科技有限公司 | C43: 35I2190001 | D43: 佰茶绿雪芽线下分销 | E43: 2202010101 | F43: 应付账款-商品采购-暂估应付款 | I43: 0000602452 | J43: 福建太姥山名茶有限公司 | K43: 0 | L43: 2654.87 | M43: -2654.87 | N43: 0 | O43: 应付账款
A44: 2240 | B44: 上海佰茶跳动科技有限公司 | C44: 46I2070001 | D44: 佰茶绿雪芽京东自营店 | E44: 2202010101 | F44: 应付账款-商品采购-暂估应付款 | I44: 0000602295 | J44: 福建绿雪芽茶业有限公司 | K44: 0 | L44: 10475.61 | M44: -10475.61 | N44: 0 | O44: 应付账款
...

Sheet 六大往来
A1: 科目2 | B1: 重分类 | C1: 供应商描述 | D1: 客户描述 | E1: 求和项:期末金额
A2: 其他应付款 | B2: =A2 -> 其他应付款 | C2: 成都声云文化传播有限公司 | D2: (空白) | E2: -340465 | G2: 应收账款 | H2: =SUMIFS(E:E,B:B,G2) -> 908206.67 | I2: =H2 -> 908206.67
A3: 其他应付款 | B3: =A3 -> 其他应付款 | C3: 福建绿雪芽茶业有限公司 | D3: (空白) | E3: -150363.47 | G3: 预付款项 | H3: =SUMIFS(E:E,B:B,G3) -> 0 | I3: =H3 -> 0
A4: 其他应付款 | B4: =A4 -> 其他应付款 | C4: 福建省天湖茶业有限公司 | D4: (空白) | E4: -112264.13 | G4: 其他应收款 | H4: =SUMIFS(E:E,B:B,G4) -> 81886.46 | I4: =H4 -> 81886.46
A5: 其他应付款 | B5: =A5 -> 其他应付款 | C5: 上海博观瑞思传媒科技有限公司 | D5: (空白) | E5: -106310.41 | G5: 应付账款 | H5: =SUMIFS(E:E,B:B,G5) -> -1260096.1 | I5: =-H5 -> 1260096.1
A6: 其他应收款 | B6: =A6 -> 其他应收款 | C6: (空白) | D6: 北京有竹居网络技术有限公司 | E6: 500 | G6: 预收款项 | H6: =SUMIFS(E:E,B:B,G6) -> -12790.19 | I6: =-H6 -> 12790.19
A7: 其他应收款 | B7: =A7 -> 其他应收款 | C7: (空白) | D7: 杭州照茗文化传播有限公司 | E7: 2838.19 | G7: 其他应付款 | H7: =SUMIFS(E:E,B:B,G7) -> -709403.01 | I7: =-H7 -> 709403.01
A8: 其他应收款 | B8: =A8 -> 其他应收款 | C8: (空白) | D8: 零星客户 | E8: 11548.27 | G8: 合计 | H8: =SUM(H2:H7) -> -992196.19
A9: 其他应收款 | B9: =A9 -> 其他应收款 | C9: (空白) | D9: 绿雪芽-京东POP旗舰店-佰茶 | E9: 5000
A10: 其他应收款 | B10: =A10 -> 其他应收款 | C10: (空白) | D10: 绿雪芽-天猫旗舰店-佰茶 | E10: 50000
A11: 其他应收款 | B11: =A11 -> 其他应收款 | C11: (空白) | D11: 绿雪芽-微信小店-佰茶 | E11: 2000
A12: 其他应收款 | B12: =A12 -> 其他应收款 | C12: (空白) | D12: 优穗信息科技(上海)有限公司 | E12: 10000
A13: 应付账款 | B13: =A13 -> 应付账款 | C13: 福建绿雪芽茶业有限公司 | D13: (空白) | E13: -633415.04
A14: 应付账款 | B14: =A14 -> 应付账款 | C14: 杭州照茗文化传播有限公司 | D14: (空白) | E14: -50141.39
A15: 应付账款 | B15: =A15 -> 应付账款 | C15: 上海璞康数据科技（集团）股份有限公司 | D15: (空白) | E15: -490297.08
A16: 应付账款 | B16: =A16 -> 应付账款 | C16: 上海璞睿供应链管理服务有限公司 | D16: (空白) | E16: -86242.61
A17: 应收账款 | B17: =A17 -> 应收账款 | C17: (空白) | D17: 绿雪芽-天猫旗舰店-佰茶 | E17: 10.01
A18: 应收账款 | B18: =A18 -> 应收账款 | C18: (空白) | D18: 上海璞康实业有限公司-内部往来 | E18: 7090.15
A19: 应收账款 | B19: =A19 -> 应收账款 | C19: (空白) | D19: 上海璞睿供应链管理服务有限公司 | E19: 901106.51
A20: 应收账款 | B20: 预收款项 | C20: (空白) | D20: 上海璞樾数据科技有限公司 | E20: -12790.19

Sheet 支付明细
A6: 账号 | B6: 账号名称 | C6: 币种 | D6: 交易日 | E6: 交易时间 | F6: 起息日 | G6: 交易类型 | H6: 借方金额 | I6: 贷方金额 | J6: 余额 | K6: 摘要 | L6: 流水号 | M6: 流程实例号 | N6: 业务名称 | O6: 用途 | P6: 业务参考号 | Q6: 业务摘要 | R6: 其它摘要 | S6: 收(付)方分行名 | T6: 收(付)方名称 | U6: 收(付)方账号 | V6: 收(付)方开户行行号 | W6: 收(付)方开户行名 | X6: 收(付)方开户行地址 | Y6: 母(子)公司账号分行名 | Z6: 母(子)公司账号 | AA6: 母(子)公司名称 | AB6: 信息标志 | AC6: 有否附件信息 | AD6: 冲账标志 | AE6: 扩展摘要 | AF6: 交易分析码 | AG6: 票据号 | AH6: 商务支付订单号 | AI6: 内部编号 | AJ6: 公司一卡通号
A7: 121983261710001 | B7: 上海佰茶跳动科技有限公司 | C7: 人民币 | D7: 2026-06-01 | E7: 16:46:58 | F7: 2026-06-01 | G7: 对公转账正常提出 | H7: 4531 | J7: 1001218.8 | K7: 茶叶赔偿款 | L7: C0247G0000ZV22Z | M7: 5204777140 | N7: 支付 | P7: 20260601162218 | T7: 戚旬璋 | U7: 6217732510417755 | W7: 中信银行济南历下支行 | X7: 山东省济南市
A8: 121983261710001 | B8: 上海佰茶跳动科技有限公司 | C8: 人民币 | D8: 2026-06-01 | E8: 16:46:58 | F8: 2026-06-01 | G8: 对公转账正常提出 | H8: 50 | J8: 1001168.8 | K8: 受理费 | L8: C0247G0000YXE1Z | M8: 5204777141 | N8: 支付 | P8: 20260601162530 | T8: 梁山县人民法院 | U8: 6228401338069328664 | W8: 中国农业银行股份有限公司梁山县支行 | X8: 山东省济宁市
A9: 121983261710001 | B9: 上海佰茶跳动科技有限公司 | C9: 人民币 | D9: 2026-06-01 | E9: 16:46:58 | F9: 2026-06-01 | G9: 对公转账正常提出 | H9: 157604.62 | J9: 843564.17 | K9: 货款 | L9: C0247G0000YXE5Z | M9: 5204777142 | N9: 支付 | P9: 20260601162651 | T9: 福建绿雪芽茶业有限公司 | U9: 13230101040010702 | W9: 中国农业银行股份有限公司福鼎市支行 | X9: 福建省宁德市
A10: 121983261710001 | B10: 上海佰茶跳动科技有限公司 | C10: 人民币 | D10: 2026-06-01 | E10: 16:46:58 | F10: 2026-06-01 | G10: 对公转账正常提出 | H10: 37357.35 | J10: 806206.82 | K10: 服务费 | L10: C0247G000143W2Z | M10: 5204777143 | N10: 支付 | P10: 20260601162757 | T10: 福建省天湖茶业有限公司 | U10: 13230201040001493 | W10: 中国农业银行股份有限公司福鼎中汇支行 | X10: 福建省宁德市
A11: 121983261710001 | B11: 上海佰茶跳动科技有限公司 | C11: 人民币 | D11: 2026-06-01 | E11: 16:46:58 | F11: 2026-06-01 | G11: 对公转账正常提出 | H11: 36000 | J11: 770206.82 | K11: 服务费 | L11: C0247G000131OQZ | M11: 5204777144 | N11: 支付 | P11: 20260601162917 | T11: 上海璞康数据科技（集团）股份有限公司 | U11: 121935940910901 | W11: 招商银行 | X11: 上海市
A12: 121983261710001 | B12: 上海佰茶跳动科技有限公司 | C12: 人民币 | D12: 2026-06-02 | E12: 07:46:10 | F12: 2026-06-02 | G12: 企业银行各项费用 | H12: 99.91 | J12: 770106.91 | K12: 网银支付-跨行-异地手续费 | L12: C0247G1000K5X8Z | T12: 网上电子汇划收入 | U12: 912156050071101810
A13: 121983261710001 | B13: 上海佰茶跳动科技有限公司 | C13: 人民币 | D13: 2026-06-02 | E13: 07:46:11 | F13: 2026-06-02 | G13: 企业银行各项费用 | H13: 14.25 | J13: 770092.66 | K13: 网银支付-行内-异地手续费 | L13: C0247G1000PINJZ | T13: 网上电子汇划收入 | U13: 912156050071101810
A14: 121983261710001 | B14: 上海佰茶跳动科技有限公司 | C14: 人民币 | D14: 2026-06-02 | E14: 07:46:11 | F14: 2026-06-02 | G14: 企业银行各项费用 | H14: 25 | J14: 770067.66 | K14: 网上企业银行-网上企业银行服务费 | L14: C0247G1000K5XCZ | T14: 对公中间业务收入-网上其他收入 | U14: 912156050070019810
A15: 121983261710001 | B15: 上海佰茶跳动科技有限公司 | C15: 人民币 | D15: 2026-06-03 | E15: 13:22:59 | F15: 2026-06-03 | G15: 提回对公户收款 | I15: 240 | J15: 770307.66 | K15: SPFK-20260602-0007 | L15: C0247G200194WTZ | M15: 7201273450 | N15: 支付 | P15: HELIOSZF202606030385365743 | T15: 上海璞康实业有限公司 | U15: 121902412710502 | W15: 招商银行上海分行营业部 | X15: 上海市
A16: 121983261710001 | B16: 上海佰茶跳动科技有限公司 | C16: 人民币 | D16: 2026-06-05 | E16: 07:43:15 | F16: 2026-06-05 | G16: 银联TOKEN贷记对公户入账 | I16: 100000 | J16: 870307.66 | K16: 佰茶天猫店 | L16: C0247G40001KC5Z | T16: 支付宝支付科技有限公司 | U16: 20887704416849330156 | W16: 支付宝-备付金账户
A17: 121983261710001 | B17: 上海佰茶跳动科技有限公司 | C17: 人民币 | D17: 2026-06-05 | E17: 10:56:34 | F17: 2026-06-05 | G17: IBPS对公提回贷记 | I17: 260000 | J17: 1130307.7 | K17: NJCB0202606051056320137724345064 | L17: C0247G40009GQTZ | T17: 南京银行-平台商户待清算资金（抖音） | U17: 050115620120040500020 | W17: 南京银行股份有限公司
A18: 121983261710001 | B18: 上海佰茶跳动科技有限公司 | C18: 人民币 | D18: 2026-06-05 | E18: 11:50:38 | F18: 2026-06-05 | G18: 提回对公户收款 | I18: 2107.35 | J18: 1132415 | K18: SPFK-20260428-0085 | L18: C0247G4000JQYQZ | M18: 7201995645 | N18: 支付 | P18: HELIOSZF202606050569147027 | T18: 上海璞康实业有限公司 | U18: 121902412710502 | W18: 招商银行上海分行营业部 | X18: 上海市
A19: 121983261710001 | B19: 上海佰茶跳动科技有限公司 | C19: 人民币 | D19: 2026-06-05 | E19: 13:46:17 | F19: 2026-06-05 | G19: 提回对公户收款 | I19: 3676.9 | J19: 1136091.9 | K19: SPFK-20260603-0016 | L19: C0247G4000OOV0Z | M19: 7202274983 | N19: 支付 | P19: HELIOSZF202606050785319773 | T19: 上海璞康实业有限公司 | U19: 121902412710502 | W19: 招商银行上海分行营业部 | X19: 上海市
A20: 121983261710001 | B20: 上海佰茶跳动科技有限公司 | C20: 人民币 | D20: 2026-06-08 | E20: 13:25:53 | F20: 2026-06-08 | G20: 网联付款申请收款 | I20: 0.13 | J20: 1136092 | K20: 电商商家入驻代付打款验证 | L20: C0247G7000N9ASZ | T20: 北京有竹居网络技术有限公司 | U20: 8020220721560096 | W20: 抖音支付
A21: 121983261710001 | B21: 上海佰茶跳动科技有限公司 | C21: 人民币 | D21: 2026-06-08 | E21: 15:46:50 | F21: 2026-06-08 | G21: 提回对公户收款 | I21: 1396.5 | J21: 1137488.5 | K21: SPFK-20260605-0024 | L21: C0247G7000X8YFZ | M21: 7202904519 | N21: 支付 | P21: HELIOSZF202606081369591820 | T21: 上海璞康实业有限公司 | U21: 121902412710502 | W21: 招商银行上海分行营业部 | X21: 上海市
A22: 121983261710001 | B22: 上海佰茶跳动科技有限公司 | C22: 人民币 | D22: 2026-06-09 | E22: 16:01:05 | F22: 2026-06-09 | G22: 网联对公网关支付 | H22: 70000 | J22: 1067488.5 | K22: 天猫店铺充值 | L22: C0247G8000V2M7Z | M22: BH04220019 | N22: 商务支付 | P22: 20260609151809 | Q22: 天猫店铺充值 | T22: 淘宝（中国）软件有限公司 | U22: 20886110899414850156 | W22: 支付宝支付科技有限公司
A23: 121983261710001 | B23: 上海佰茶跳动科技有限公司 | C23: 人民币 | D23: 2026-06-09 | E23: 16:02:09 | F23: 2026-06-09 | G23: 对公转账正常提出 | H23: 5850 | J23: 1061638.5 | K23: 货款 | L23: C0247G8000V33TZ | M23: 5204777145 | N23: 支付 | P23: 20260609135102 | T23: 福建绿雪芽茶业有限公司 | U23: 13230101040010702 | W23: 中国农业银行股份有限公司福鼎市支行 | X23: 福建省宁德市
A24: 121983261710001 | B24: 上海佰茶跳动科技有限公司 | C24: 人民币 | D24: 2026-06-09 | E24: 16:02:09 | F24: 2026-06-09 | G24: 对公转账正常提出 | H24: 66422.24 | J24: 995216.3 | K24: 货款 | L24: C0247G8000V33XZ | M24: 5204777146 | N24: 支付 | P24: 20260609135141 | T24: 福建绿雪芽茶业有限公司 | U24: 13230101040010702 | W24: 中国农业银行股份有限公司福鼎市支行 | X24: 福建省宁德市
A25: 121983261710001 | B25: 上海佰茶跳动科技有限公司 | C25: 人民币 | D25: 2026-06-09 | E25: 16:02:09 | F25: 2026-06-09 | G25: 对公转账正常提出 | H25: 50946 | J25: 944270.3 | K25: 货款 | L25: C0247G80010EIOZ | M25: 5204777147 | N25: 支付 | P25: 20260609135224 | T25: 福建绿雪芽茶业有限公司 | U25: 13230101040010702 | W25: 中国农业银行股份有限公司福鼎市支行 | X25: 福建省宁德市
A26: 121983261710001 | B26: 上海佰茶跳动科技有限公司 | C26: 人民币 | D26: 2026-06-09 | E26: 16:02:09 | F26: 2026-06-09 | G26: 对公转账正常提出 | H26: 122355.86 | J26: 821914.44 | K26: 服务费 | L26: C0247G8000W71VZ | M26: 5204777148 | N26: 支付 | P26: 20260609135307 | T26: 成都声云文化传播有限公司 | U26: 128916733510000 | W26: 招商银行 | X26: 四川省成都市
A27: 121983261710001 | B27: 上海佰茶跳动科技有限公司 | C27: 人民币 | D27: 2026-06-10 | E27: 16:47:32 | F27: 2026-06-10 | G27: 税款 | H27: 2139.02 | J27: 819775.42 | K27: 00TX:000990:20260610:000YST26061016EHZ6IZ:实时缴税:税单号:626061011888867167 | L27: C0247G90019L74Z | T27: 国库待结算款项-暂收款 | U27: 090000000002371002 | W27: 中华人民共和国国家金库上海市分库
A28: 121983261710001 | B28: 上海佰茶跳动科技有限公司 | C28: 人民币 | D28: 2026-06-11 | E28: 11:29:53 | F28: 2026-06-11 | G28: 对公转账正常提出 | H28: 699.3 | J28: 819076.12 | K28: 货款 | L28: C0247GA000G313Z | M28: 5204777149 | N28: 支付 | P28: 20260611085309 | T28: 福建绿雪芽茶业有限公司 | U28: 13230101040010702 | W28: 中国农业银行股份有限公司福鼎市支行 | X28: 福建省宁德市
A29: 121983261710001 | B29: 上海佰茶跳动科技有限公司 | C29: 人民币 | D29: 2026-06-11 | E29: 11:29:53 | F29: 2026-06-11 | G29: 对公转账正常提出 | H29: 407 | J29: 818669.12 | K29: 报销 | L29: C0247GA000H52AZ | M29: 5208329160 | N29: 支付 | P29: 20260611085407 | T29: 张豆豆 | U29: 6214832632751827 | W29: 招商银行 | X29: 上海市
A30: 121983261710001 | B30: 上海佰茶跳动科技有限公司 | C30: 人民币 | D30: 2026-06-11 | E30: 11:31:03 | F30: 2026-06-11 | G30: 网联对公网关支付 | H30: 20000 | J30: 798669.12 | K30: 京东店铺充值 | L30: C0247GA000G3N3Z | M30: BH04236629 | N30: 商务支付 | P30: 20260611085030 | Q30: 京东店铺充值 | T30: 广西京东星辰电子商务有限公司 | U30: 118228906002 | W30: 网银在线（北京）支付科技有限公司
A31: 121983261710001 | B31: 上海佰茶跳动科技有限公司 | C31: 人民币 | D31: 2026-06-11 | E31: 15:56:59 | F31: 2026-06-11 | G31: 提回对公户收款 | I31: 76.9 | J31: 798746.02 | K31: 转账 | L31: C0247GA0012PPNZ | T31: 郁弘芳 | U31: 6214851830873936 | W31: 招商银行
A32: 121983261710001 | B32: 上海佰茶跳动科技有限公司 | C32: 人民币 | D32: 2026-06-11 | E32: 16:45:26 | F32: 2026-06-11 | G32: 对公转账正常提出 | H32: 1084.65 | J32: 797661.37 | K32: 报销款 | L32: C0247GA00109HMZ | M32: 5208329161 | N32: 支付 | P32: 20260611160518 | T32: 宋杨阳 | U32: 6214833451116035 | W32: 招商银行 | X32: 上海市
A33: 121983261710001 | B33: 上海佰茶跳动科技有限公司 | C33: 人民币 | D33: 2026-06-11 | E33: 16:45:31 | F33: 2026-06-11 | G33: 对公转账正常提出 | H33: 203 | J33: 797458.37 | K33: 报销款 | L33: C0247GA0016ND0Z | M33: 5208329162 | N33: 支付 | P33: 20260611160601 | T33: 陈晓君 | U33: 6214832639085732 | W33: 招商银行 | X33: 上海市
A34: 121983261710001 | B34: 上海佰茶跳动科技有限公司 | C34: 人民币 | D34: 2026-06-11 | E34: 16:45:31 | F34: 2026-06-11 | G34: 对公转账正常提出 | H34: 1871.67 | J34: 795586.7 | K34: 报销款 | L34: C0247GA0014IMDZ | M34: 5208329164 | N34: 支付 | P34: 20260611164331 | T34: 张豆豆 | U34: 6214832632751827 | W34: 招商银行 | X34: 上海市
A35: 121983261710001 | B35: 上海佰茶跳动科技有限公司 | C35: 人民币 | D35: 2026-06-12 | E35: 15:50:31 | F35: 2026-06-12 | G35: 提回对公户收款 | I35: 3820.5 | J35: 799407.2 | K35: SPFK-20260604-0020 | L35: C0247GB0015BXSZ | M35: 7204422003 | N35: 支付 | P35: HELIOSZF202606120263339357 | T35: 上海璞康实业有限公司 | U35: 121902412710502 | W35: 招商银行上海分行营业部 | X35: 上海市
A36: 121983261710001 | B36: 上海佰茶跳动科技有限公司 | C36: 人民币 | D36: 2026-06-15 | E36: 12:01:36 | F36: 2026-06-15 | G36: 税款 | H36: 23638.6 | J36: 775768.6 | K36: 00TX:000990:20260615:000YST26061512FXI52E:实时缴税:税单号:431016260600965524 | L36: C0247GE000MFA0Z | T36: 国库待结算款项-暂收款 | U36: 090000000002371002 | W36: 中华人民共和国国家金库上海市分库 | AB36: 1 | AF36: TXGATR
A37: 121983261710001 | B37: 上海佰茶跳动科技有限公司 | C37: 人民币 | D37: 2026-06-15 | E37: 14:27:10 | F37: 2026-06-15 | G37: 上海同城二期代收业务（公共费项） | H37: 9142 | J37: 766626.6 | K37: 公积金:业务唯一编号2026061500757404 | L37: C0247GE0015WXCZ | T37: 上海市公积金管理中心(房改资金) | U37: 31001502588050000452-0005 | W37: 中国建设银行股份有限公司上海市分行 | AB37: 1 | AF37: GATR
A38: 121983261710001 | B38: 上海佰茶跳动科技有限公司 | C38: 人民币 | D38: 2026-06-15 | E38: 17:19:48 | F38: 2026-06-15 | G38: 代发工资 | H38: 92024.26 | J38: 674602.34 | K38: 工资 | L38: C0247GE001MT6KZ | M38: 4546670419 | N38: 代发工资 | P38: 20260615164638 | AB38: 1 | AE38: 3005J5H1ZK | AF38: AIGATR
A39: 121983261710001 | B39: 上海佰茶跳动科技有限公司 | C39: 人民币 | D39: 2026-06-15 | E39: 17:20:00 | F39: 2026-06-15 | G39: 代发手续费 | H39: 3.5 | J39: 674598.84 | K39: 批量代发付费 | L39: C0247GE001MT9TZ | AB39: 1 | AF39: GATR
A40: 121983261710001 | B40: 上海佰茶跳动科技有限公司 | C40: 人民币 | D40: 2026-06-15 | E40: 19:42:45 | F40: 2026-06-15 | G40: 对公转账正常提出 | H40: 1029.42 | J40: 673569.42 | K40: 彩袋、不干胶款 | L40: C0247GE0021EQFZ | M40: 5208329166 | N40: 支付 | P40: 20260615165030 | T40: 广东优心选商业有限公司 | U40: 7559717853100000003669485 | W40: 招商银行 | X40: 广东省广州市 | AB40: 1 | AE40: 17S037G900000K085815 | AF40: CPGATR
A41: 121983261710001 | B41: 上海佰茶跳动科技有限公司 | C41: 人民币 | D41: 2026-06-15 | E41: 20:26:51 | F41: 2026-06-15 | G41: 提回对公户收款 | I41: 14238 | J41: 687807.42 | K41: 货款 | L41: C0247GE0025TO3Z | M41: 8217754292 | N41: 支付 | P41: 20260615202102 | T41: 广州市简健农业科技有限公司 | U41: 120930476910001 | W41: 招商银行广州分行广州丰兴支行 | X41: 广东省广州市 | AE41: 69S037G8000005165445 | AF41: CPGATR
A42: 121983261710001 | B42: 上海佰茶跳动科技有限公司 | C42: 人民币 | D42: 2026-06-16 | E42: 16:54:11 | F42: 2026-06-16 | G42: 对公转账正常提出 | H42: 29400 | J42: 658407.42 | K42: 货款 | L42: C0247GF0013R7XZ | M42: 5208329167 | N42: 支付 | P42: 20260616163855 | T42: 福建绿雪芽茶业有限公司 | U42: 13230101040010702 | W42: 中国农业银行股份有限公司福鼎市支行 | X42: 福建省宁德市 | AB42: 1 | AE42: 17S037G900000H127373 | AF42: CPGATR
A43: 121983261710001 | B43: 上海佰茶跳动科技有限公司 | C43: 人民币 | D43: 2026-06-16 | E43: 16:54:11 | F43: 2026-06-16 | G43: 对公转账正常提出 | H43: 91000 | J43: 567407.42 | K43: 货款 | L43: C0247GF001A72KZ | M43: 5208329168 | N43: 支付 | P43: 20260616163932 | T43: 福建绿雪芽茶业有限公司 | U43: 13230101040010702 | W43: 中国农业银行股份有限公司福鼎市支行 | X43: 福建省宁德市 | AB43: 1 | AE43: 17S037G900000M219982 | AF43: CPGATR
A44: 121983261710001 | B44: 上海佰茶跳动科技有限公司 | C44: 人民币 | D44: 2026-06-18 | E44: 15:08:54 | F44: 2026-06-18 | G44: 对公转账正常提出 | H44: 112689.03 | J44: 454718.39 | K44: 服务费 | L44: C0247GH0011EYKZ | M44: 5208329165 | N44: 支付 | P44: 20260615164937 | T44: 上海博观瑞思传媒科技有限公司 | U44: 91110078801600002699 | W44: 上海浦东发展银行北京阜成支行 | X44: 北京市 | AB44: 1 | AE44: 17S037GG00000A155321 | AF44: CPGATR
A45: 121983261710001 | B45: 上海佰茶跳动科技有限公司 | C45: 人民币 | D45: 2026-06-21 | E45: 02:25:50 | F45: 2026-06-21 | G45: 账户结息 | I45: 182.36 | J45: 454900.75 | K45: 收息，结息账号: 121983261710001 | L45: C0247GK0006715Z | T45: 应付利息-单位活期存款利息-自动计提 | U45: 912156020611001810 | AF45: YAIN
