Workbook

Sheet 日报
A1: 太樾旗舰店推广报表
A2: 目标ROI | B2: 渠道 | C2: 日期 | D2: 12月总计 | E2: 46011 | F2: 46012 | G2: 46013 | H2: 46014 | I2: 46015 | J2: 46016 | K2: 46017 | L2: 46018 | M2: 46019 | N2: 46020 | O2: 46021 | P2: 46022 | Q2: 1月总计 | R2: 46023 | S2: 46024 | T2: 46025 | U2: 46026 | V2: 46027 | W2: 46028 | X2: 46029 | Y2: 46030 | Z2: 46031 | AA2: 46032 | AB2: 46033 | AC2: 46034 | AD2: 46035 | AE2: 46036 | AF2: 46037 | AG2: 46038 | AH2: 46039 | AI2: 46040 | AJ2: 46041 | AK2: 46042 | AL2: 46043 | AM2: 46044 | AN2: 46045 | AO2: 46046 | AP2: 46047 | AQ2: 46048 | AR2: 46049 | AS2: 46050 | AT2: 46051 | AU2: 46052 | AV2: 46053 | AW2: 2月总计 | AX2: 46054 | AY2: 46055 | AZ2: 46056 | BA2: 46057 | BB2: 46058 | BC2: 46059 | BD2: 46060 | BE2: 46061 | BF2: 46062 | BG2: 46063 | BH2: 46064 | BI2: 46065 | BJ2: 46066 | BK2: 46067 | BL2: 46068 | BM2: 46069 | BN2: 46070 | BO2: 46071 | BP2: 46072 | BQ2: 46073 | BR2: 46074 | BS2: 46075 | BT2: 46076 | BU2: 46077 | BV2: 46078 | BW2: 46079 | BX2: 46080 | BY2: 46081 | BZ2: 3月总计 | CA2: 46082 | CB2: 46083 | CC2: 46084 | CD2: 46085 | CE2: 46086 | CF2: 46087 | CG2: 46088 | CH2: 46089 | CI2: 46090 | CJ2: 46091 | CK2: 46092 | CL2: 46093 | CM2: 46094 | CN2: 46095 | CO2: 46096 | CP2: 46097 | CQ2: 46098 | CR2: 46099 | CS2: 46100 | CT2: 46101 | CU2: 46102 | CV2: 46103 | CW2: 46104 | CX2: 46105 | CY2: 46106 | CZ2: 46107 | DA2: 46108 | DB2: 46109 | DC2: 46110 | DD2: 46111 | DE2: 46112 | DF2: 4月总计 | DG2: 46113 | DH2: 46114 | DI2: 46115 | DJ2: 46116 | DK2: 46117 | DL2: 46118 | DM2: 46119 | DN2: 46120 | DO2: 46121 | DP2: 46122 | DQ2: 46123 | DR2: 46124 | DS2: 46125 | DT2: 46126 | DU2: 46127 | DV2: 46128 | DW2: 46129 | DX2: 46130 | DY2: 46131 | DZ2: 46132 | EA2: 46133 | EB2: 46134 | EC2: 46135 | ED2: 46136 | EE2: 46137 | EF2: 46138 | EG2: 46139 | EH2: 46140 | EI2: 46141 | EJ2: 46142 | EK2: 5月总计 | EL2: 46143 | EM2: 46144 | EN2: 46145 | EO2: 46146 | EP2: 46147 | EQ2: 46148 | ER2: 46149 | ES2: 46150 | ET2: 46151 | EU2: 46152 | EV2: 46153 | EW2: 46154 | EX2: 46155 | EY2: 46156 | EZ2: 46157 | FA2: 46158 | FB2: 46159 | FC2: 46160 | FD2: 46161 | FE2: 46162 | FF2: 46163 | FG2: 46164 | FH2: 46165 | FI2: 46166 | FJ2: 46167 | FK2: 46168 | FL2: 46169 | FM2: 46170 | FN2: 46171 | FO2: 46172 | FP2: 46173 | FQ2: 6月总计 | FR2: 46174 | FS2: 46175 | FT2: 46176 | FU2: 46177 | FV2: 46178 | FW2: 46179 | FX2: 46180 | FY2: 46181 | FZ2: 46182 | GA2: 46183 | GB2: 46184 | GC2: 46185 | GD2: 46186 | GE2: 46187 | GF2: 46188 | GG2: 46189 | GH2: 46190 | GI2: 46191 | GJ2: 46192 | GK2: 46193 | GL2: 46194 | GM2: 46195 | GN2: 46196 | GO2: 46197 | GP2: 46198
B3: 推广汇总 | C3: 花费 | D3: =SUM(E3:P3) -> #REF! | E3: =E20+E29+E38+E47+E56+E65 -> #REF! | F3: =F20+F29+F38+F47+F56+F65 -> #REF! | G3: =G20+G29+G38+G47+G56+G65 -> #REF! | H3: =H20+H29+H38+H47+H56+H65 -> #REF! | I3: =I20+I29+I38+I47+I56+I65 -> #REF! | J3: =J20+J29+J38+J47+J56+J65 -> #REF! | K3: =K20+K29+K38+K47+K56+K65 -> #REF! | L3: =L20+L29+L38+L47+L56+L65 -> #REF! | ... P3: =P20+P29+P38+P47+P56+P65 -> #REF! | Q3: =SUM(R3:AV3) -> 10202.72 | R3: =R20+R29+R38+R47+R56+R65 -> 230.73 | S3: =S20+S29+S38+S47+S56+S65 -> 229.7 | T3: =T20+T29+T38+T47+T56+T65 -> 286.36 | U3: =U20+U29+U38+U47+U56+U65 -> 428.62 | V3: =V20+V29+V38+V47+V56+V65 -> 348.76 | W3: =W20+W29+W38+W47+W56+W65 -> 374.2 | X3: =X20+X29+X38+X47+X56+X65 -> 313.85 | Y3: =Y20+Y29+Y38+Y47+Y56+Y65 -> 377 | ... AV3: =AV20+AV29+AV38+AV47+AV56+AV65 -> 267.44 | AW3: =SUM(AX3:BY3) -> 5679.7 | AX3: =AX20+AX29+AX38+AX47+AX56+AX65 -> 273.95 | AY3: =AY20+AY29+AY38+AY47+AY56+AY65 -> 285.71 | AZ3: =AZ20+AZ29+AZ38+AZ47+AZ56+AZ65 -> 260.76 | BA3: =BA20+BA29+BA38+BA47+BA56+BA65 -> 261.42 | BB3: =BB20+BB29+BB38+BB47+BB56+BB65 -> 272.63 | BC3: =BC20+BC29+BC38+BC47+BC56+BC65 -> 261.13 | BD3: =BD20+BD29+BD38+BD47+BD56+BD65 -> 256.67 | BE3: =BE20+BE29+BE38+BE47+BE56+BE65 -> 270.07 | ... BY3: =BY20+BY29+BY38+BY47+BY56+BY65 -> 235.04 | BZ3: =SUM(CA3:DE3) -> 10435.87 | CA3: =CA20+CA29+CA38+CA47+CA56+CA65 -> 215.8 | CB3: =CB20+CB29+CB38+CB47+CB56+CB65 -> 225.78 | CC3: =CC20+CC29+CC38+CC47+CC56+CC65 -> 237.53 | CD3: =CD20+CD29+CD38+CD47+CD56+CD65 -> 306.96 | CE3: =CE20+CE29+CE38+CE47+CE56+CE65 -> 338.82 | CF3: =CF20+CF29+CF38+CF47+CF56+CF65 -> 306.52 | CG3: =CG20+CG29+CG38+CG47+CG56+CG65 -> 231.74 | CH3: =CH20+CH29+CH38+CH47+CH56+CH65 -> 273.86 | ... DE3: =DE20+DE29+DE38+DE47+DE56+DE65 -> 321.02 | DF3: =SUM(DG3:EJ3) -> 10737.69 | DG3: =DG20+DG29+DG38+DG47+DG56+DG65 -> 269.05 | DH3: =DH20+DH29+DH38+DH47+DH56+DH65 -> 223.4 | DI3: =DI20+DI29+DI38+DI47+DI56+DI65 -> 280.21 | DJ3: =DJ20+DJ29+DJ38+DJ47+DJ56+DJ65 -> 266.99 | DK3: =DK20+DK29+DK38+DK47+DK56+DK65 -> 338.86 | DL3: =DL20+DL29+DL38+DL47+DL56+DL65 -> 265.57 | DM3: =DM20+DM29+DM38+DM47+DM56+DM65 -> 507.4 | DN3: =DN20+DN29+DN38+DN47+DN56+DN65 -> 685.11 | ... EJ3: =EJ20+EJ29+EJ38+EJ47+EJ56+EJ65 -> 246 | EK3: =SUM(EL3:FP3) -> 10292.28 | EL3: =EL20+EL29+EL38+EL47+EL56+EL65 -> 251.35 | EM3: =EM20+EM29+EM38+EM47+EM56+EM65 -> 237.78 | EN3: =EN20+EN29+EN38+EN47+EN56+EN65 -> 257.04 | EO3: =EO20+EO29+EO38+EO47+EO56+EO65 -> 246.18 | EP3: =EP20+EP29+EP38+EP47+EP56+EP65 -> 263.29 | EQ3: =EQ20+EQ29+EQ38+EQ47+EQ56+EQ65 -> 251.64 | ER3: =ER20+ER29+ER38+ER47+ER56+ER65 -> 243.45 | ES3: =ES20+ES29+ES38+ES47+ES56+ES65 -> 438.23 | ... FP3: =FP20+FP29+FP38+FP47+FP56+FP65 -> 337.54 | FQ3: =SUM(FR3:GX3) -> 7384.34 | FR3: =FR20+FR29+FR38+FR47+FR56+FR65 -> 312.68 | FS3: =FS20+FS29+FS38+FS47+FS56+FS65 -> 300.42 | FT3: =FT20+FT29+FT38+FT47+FT56+FT65 -> 279.32 | FU3: =FU20+FU29+FU38+FU47+FU56+FU65 -> 332 | FV3: =FV20+FV29+FV38+FV47+FV56+FV65 -> 301.96 | FW3: =FW20+FW29+FW38+FW47+FW56+FW65 -> 336.92 | FX3: =FX20+FX29+FX38+FX47+FX56+FX65 -> 361.92 | FY3: =FY20+FY29+FY38+FY47+FY56+FY65 -> 357.64 | ... GP3: =GP20+GP29+GP38+GP47+GP56+GP65 -> 0
A4: 实际ROI (除品销宝) | C4: ROI | D4: =(D24+D33+D42+D51+D60+D69)/(D3) -> #REF! | E4: =(E24+E33+E42+E51+E60+E69)/(E3) -> #REF! | F4: =(F24+F33+F42+F51+F60+F69)/(F3) -> #REF! | G4: =(G24+G33+G42+G51+G60+G69)/(G3) -> #REF! | H4: =(H24+H33+H42+H51+H60+H69)/(H3) -> #REF! | I4: =(I24+I33+I42+I51+I60+I69)/(I3) -> #REF! | J4: =(J24+J33+J42+J51+J60+J69)/(J3) -> #REF! | K4: =(K24+K33+K42+K51+K60+K69)/(K3) -> #REF! | ... GP4: =(GP24+GP33+GP42+GP51+GP60+GP69)/(GP3) -> #DIV/0!
A5: =D4 -> #REF! | C5: 店铺销售额 | D5: =SUM(E5:P5) -> 39572.03 | E5: 5285.21 | F5: 351.94 | G5: 22254.41 | H5: 2589.55 | I5: 847.83 | J5: 1257.21 | K5: 231.18 | L5: 3071.4 | M5: 998 | N5: 1983.45 | O5: 701.85 | P5: 0 | Q5: =SUM(R5:AV5) -> 56457.53 | R5: 1796.9 | S5: 4627.64 | T5: 81.18 | U5: 3169.29 | V5: 3934.14 | W5: 1045.14 | X5: 86.82 | Y5: 3141.89 | Z5: 2283.55 | AA5: 464.34 | AB5: 5882.5 | AC5: 71.38 | AD5: 824.95 | AE5: 3302.01 | AF5: 235.67 | AG5: 965.87 | AH5: 955.4 | AI5: 595.85 | AJ5: 1899.68 | AK5: 742.55 | AL5: 74.1 | AM5: 879.16 | AN5: 3254.86 | AO5: 3605.35 | AP5: 2106.35 | AQ5: 971.69 | AR5: 1527.21 | AS5: 357.76 | AT5: 4015.47 | AU5: 1540.29 | AV5: 2018.54 | AW5: =SUM(AX5:BY5) -> 214430.41 | AX5: 105954.8 | AY5: 63126.76 | AZ5: 1603.24 | BA5: 11950.28 | BB5: 4024.13 | BC5: 4827.08 | BD5: 1732.22 | BE5: 2662.23 | BF5: 27.95 | BG5: 1714.09 | BQ5: 0 | BR5: 562.44 | BS5: 4360.36 | BT5: 57.27 | BU5: 3007.73 | BV5: 649.74 | BW5: 7250.41 | BX5: 615.82 | BY5: 303.86 | BZ5: =SUM(CA5:DE5) -> 75865.11 | CA5: 1645.81 | CB5: 514.64 | CC5: 19371.4 | CD5: 2896.7 | CE5: 3865.25 | CF5: 540.32 | CG5: 654.65 | CH5: 3285.2 | CI5: 2267.67 | CJ5: 1402.74 | CK5: 3288.2 | CL5: 906.18 | CM5: 2681.15 | CN5: 3487.1 | CO5: 1928.22 | CP5: 1950.16 | CQ5: 2301.99 | CR5: 6835.97 | CS5: 2445.09 | CT5: 928.53 | CU5: 1034.96 | CV5: 999.74 | CW5: 3669.31 | CX5: 1746.05 | CY5: 887.26 | CZ5: 518 | DA5: 270.77 | DB5: 1787.01 | DC5: 693.51 | DD5: 473.9 | DE5: 587.63 | DF5: =SUM(DG5:EJ5) -> 43628.54 | DG5: 252.2 | DH5: 752.64 | DI5: 1408.91 | DJ5: 978.97 | DK5: 1040.79 | DL5: 743.92 | DM5: 4088.38 | DN5: 1736.2 | DO5: 4668.49 | DP5: 1985.64 | DQ5: 660.3 | DR5: 343.54 | DS5: 738.95 | DT5: 1984.44 | DU5: 4053.14 | DV5: 1559.09 | DW5: 502.12 | DX5: 965.11 | DY5: 1529.09 | DZ5: 508.41 | EA5: 26.1 | EB5: 570.05 | EC5: 1654.72 | ED5: 4636.29 | EE5: 708.12 | EF5: 940.43 | EG5: 1171.27 | EH5: 2609.61 | EI5: 172.5 | EJ5: 639.12 | EK5: =SUM(EL5:FP5) -> 54561.76 | EL5: 217.84 | EM5: 345.91 | EN5: 108 | EO5: 318.75 | EP5: 3300.33 | EQ5: 451.5 | ER5: 10780.74 | ES5: 607.46 | ET5: 2321.59 | EU5: 471.97 | EV5: 472.97 | EW5: 706.64 | EX5: 443.08 | EY5: 888.04 | EZ5: 2054.76 | FA5: 5023.51 | FB5: 1260.35 | FC5: 142 | FD5: 547.4 | FE5: 1628.4 | FF5: 9940.79 | FG5: 1711.8 | FH5: 644.2 | FI5: 744.09 | FJ5: 400.53 | FK5: 636.45 | FL5: 4822.18 | FM5: 1525.46 | FN5: 549.27 | FO5: 1062.17 | FP5: 433.58 | FQ5: =SUM(FR5:GX5) -> 32437.81 | FR5: 476.16 | FS5: 1515.25 | FT5: 1724.26 | FU5: 1081.31 | FV5: 3335.66 | FW5: 348.71 | FX5: 1286.86 | FY5: 254.57 | FZ5: 1054.93 | GA5: 3428.62 | GB5: 835.6 | GC5: 271.49 | GD5: 1427.73 | GE5: 4931.24 | GF5: 3302.78 | GG5: 792.18 | GH5: 444.45 | GI5: 394.95 | GJ5: 944.65 | GK5: 929.89 | GL5: 457.8 | GM5: 798.18 | GN5: 799.18 | GO5: 800.18 | GP5: 801.18
C6: 费率 | D6: =D3/D5 -> #REF! | E6: =E3/E5 -> #REF! | F6: =F3/F5 -> #REF! | G6: =G3/G5 -> #REF! | H6: =H3/H5 -> #REF! | I6: =I3/I5 -> #REF! | J6: =J3/J5 -> #REF! | K6: =K3/K5 -> #REF! | ... GP6: =GP3/GP5 -> 0
C7: 花费(除淘宝客) | D7: =SUM(E7:P7) -> #REF! | E7: =E20+#REF!+E38+E47 -> #REF! | F7: =F20+#REF!+F38+F47 -> #REF! | G7: =G20+#REF!+G38+G47 -> #REF! | H7: =H20+#REF!+H38+H47 -> #REF! | I7: =I20+#REF!+I38+I47 -> #REF! | J7: =J20+#REF!+J38+J47 -> #REF! | K7: =K20+#REF!+K38+K47 -> #REF! | L7: =L20+#REF!+L38+L47 -> #REF! | ... P7: =P20+#REF!+P38+P47 -> #REF! | Q7: =SUM(R7:AV7) -> #REF! | R7: =R20+#REF!+R38+R47 -> #REF! | S7: =S20+#REF!+S38+S47 -> #REF! | T7: =T20+#REF!+T38+T47 -> #REF! | U7: =U20+#REF!+U38+U47 -> #REF! | V7: =V20+#REF!+V38+V47 -> #REF! | W7: =W20+#REF!+W38+W47 -> #REF! | X7: =X20+#REF!+X38+X47 -> #REF! | Y7: =Y20+#REF!+Y38+Y47 -> #REF! | ... AV7: =AV20+#REF!+AV38+AV47 -> #REF! | AW7: =SUM(AX7:BY7) -> #REF! | AX7: =AX20+#REF!+AX38+AX47 -> #REF! | AY7: =AY20+#REF!+AY38+AY47 -> #REF! | AZ7: =AZ20+#REF!+AZ38+AZ47 -> #REF! | BA7: =BA20+#REF!+BA38+BA47 -> #REF! | BB7: =BB20+#REF!+BB38+BB47 -> #REF! | BC7: =BC20+#REF!+BC38+BC47 -> #REF! | BD7: =BD20+#REF!+BD38+BD47 -> #REF! | BE7: =BE20+#REF!+BE38+BE47 -> #REF! | ... BY7: =BY20+#REF!+BY38+BY47 -> #REF! | BZ7: =SUM(CA7:DE7) -> #REF! | CA7: =CA20+#REF!+CA38+CA47 -> #REF! | CB7: =CB20+#REF!+CB38+CB47 -> #REF! | CC7: =CC20+#REF!+CC38+CC47 -> #REF! | CD7: =CD20+#REF!+CD38+CD47 -> #REF! | CE7: =CE20+#REF!+CE38+CE47 -> #REF! | CF7: =CF20+#REF!+CF38+CF47 -> #REF! | CG7: =CG20+#REF!+CG38+CG47 -> #REF! | CH7: =CH20+#REF!+CH38+CH47 -> #REF! | ... DE7: =DE20+#REF!+DE38+DE47 -> #REF! | DF7: =SUM(DG7:EJ7) -> #REF! | DG7: =DG20+#REF!+DG38+DG47 -> #REF! | DH7: =DH20+#REF!+DH38+DH47 -> #REF! | DI7: =DI20+#REF!+DI38+DI47 -> #REF! | DJ7: =DJ20+#REF!+DJ38+DJ47 -> #REF! | DK7: =DK20+#REF!+DK38+DK47 -> #REF! | DL7: =DL20+#REF!+DL38+DL47 -> #REF! | DM7: =DM20+#REF!+DM38+DM47 -> #REF! | DN7: =DN20+#REF!+DN38+DN47 -> #REF! | ... EJ7: =EJ20+#REF!+EJ38+EJ47 -> #REF! | EK7: =SUM(EL7:FP7) -> #REF! | EL7: =EL20+#REF!+EL38+EL47 -> #REF! | EM7: =EM20+#REF!+EM38+EM47 -> #REF! | EN7: =EN20+#REF!+EN38+EN47 -> #REF! | EO7: =EO20+#REF!+EO38+EO47 -> #REF! | EP7: =EP20+#REF!+EP38+EP47 -> #REF! | EQ7: =EQ20+#REF!+EQ38+EQ47 -> #REF! | ER7: =ER20+#REF!+ER38+ER47 -> #REF! | ES7: =ES20+#REF!+ES38+ES47 -> #REF! | ... FP7: =FP20+#REF!+FP38+FP47 -> #REF! | FQ7: =SUM(FR7:GX7) -> #REF! | FR7: =FR20+#REF!+FR38+FR47 -> #REF! | FS7: =FS20+#REF!+FS38+FS47 -> #REF! | FT7: =FT20+#REF!+FT38+FT47 -> #REF! | FU7: =FU20+#REF!+FU38+FU47 -> #REF! | FV7: =FV20+#REF!+FV38+FV47 -> #REF! | FW7: =FW20+#REF!+FW38+FW47 -> #REF! | FX7: =FX20+#REF!+FX38+FX47 -> #REF! | FY7: =FY20+#REF!+FY38+FY47 -> #REF! | ... GP7: =GP20+#REF!+GP38+GP47 -> #REF!
C8: 费率(除淘宝客) | D8: =D7/D5 -> #REF! | E8: =E7/E5 -> #REF! | F8: =F7/F5 -> #REF! | G8: =G7/G5 -> #REF! | H8: =H7/H5 -> #REF! | I8: =I7/I5 -> #REF! | J8: =J7/J5 -> #REF! | K8: =K7/K5 -> #REF! | ... GP8: =GP7/GP5 -> #REF!
C9: ROI(含品销宝) | D9: =D15/D7 -> #REF! | E9: =E15/E7 -> #REF! | F9: =F15/F7 -> #REF! | G9: =G15/G7 -> #REF! | H9: =H15/H7 -> #REF! | I9: =I15/I7 -> #REF! | J9: =J15/J7 -> #REF! | K9: =K15/K7 -> #REF! | ... GP9: =GP15/GP7 -> #REF!
A10: 店铺GMV | C10: 点击量 | D10: =SUM(E10:P10) -> #REF! | E10: =E21+E30+E48+E39+E57+E66 -> #REF! | F10: =F21+F30+F48+F39+F57+F66 -> #REF! | G10: =G21+G30+G48+G39+G57+G66 -> #REF! | H10: =H21+H30+H48+H39+H57+H66 -> #REF! | I10: =I21+I30+I48+I39+I57+I66 -> #REF! | J10: =J21+J30+J48+J39+J57+J66 -> #REF! | K10: =K21+K30+K48+K39+K57+K66 -> #REF! | L10: =L21+L30+L48+L39+L57+L66 -> #REF! | ... P10: =P21+P30+P48+P39+P57+P66 -> #REF! | Q10: =SUM(R10:AV10) -> 6166 | R10: =R21+R30+R48+R39+R57+R66 -> 143 | S10: =S21+S30+S48+S39+S57+S66 -> 188 | T10: =T21+T30+T48+T39+T57+T66 -> 201 | U10: =U21+U30+U48+U39+U57+U66 -> 264 | V10: =V21+V30+V48+V39+V57+V66 -> 244 | W10: =W21+W30+W48+W39+W57+W66 -> 196 | X10: =X21+X30+X48+X39+X57+X66 -> 238 | Y10: =Y21+Y30+Y48+Y39+Y57+Y66 -> 204 | ... AV10: =AV21+AV30+AV48+AV39+AV57+AV66 -> 175 | AW10: =SUM(AX10:BY10) -> 5850 | AX10: =AX21+AX30+AX48+AX39+AX57+AX66 -> 214 | AY10: =AY21+AY30+AY48+AY39+AY57+AY66 -> 244 | AZ10: =AZ21+AZ30+AZ48+AZ39+AZ57+AZ66 -> 210 | BA10: =BA21+BA30+BA48+BA39+BA57+BA66 -> 251 | BB10: =BB21+BB30+BB48+BB39+BB57+BB66 -> 223 | BC10: =BC21+BC30+BC48+BC39+BC57+BC66 -> 239 | BD10: =BD21+BD30+BD48+BD39+BD57+BD66 -> 176 | BE10: =BE21+BE30+BE48+BE39+BE57+BE66 -> 221 | ... BY10: =BY21+BY30+BY48+BY39+BY57+BY66 -> 224 | BZ10: =SUM(CA10:DE10) -> 9876 | CA10: =CA21+CA30+CA48+CA39+CA57+CA66 -> 245 | CB10: =CB21+CB30+CB48+CB39+CB57+CB66 -> 223 | CC10: =CC21+CC30+CC48+CC39+CC57+CC66 -> 236 | CD10: =CD21+CD30+CD48+CD39+CD57+CD66 -> 221 | CE10: =CE21+CE30+CE48+CE39+CE57+CE66 -> 348 | CF10: =CF21+CF30+CF48+CF39+CF57+CF66 -> 288 | CG10: =CG21+CG30+CG48+CG39+CG57+CG66 -> 230 | CH10: =CH21+CH30+CH48+CH39+CH57+CH66 -> 306 | ... DE10: =DE21+DE30+DE48+DE39+DE57+DE66 -> 360 | DF10: =SUM(DG10:EJ10) -> 12247 | DG10: =DG21+DG30+DG48+DG39+DG57+DG66 -> 370 | DH10: =DH21+DH30+DH48+DH39+DH57+DH66 -> 305 | DI10: =DI21+DI30+DI48+DI39+DI57+DI66 -> 353 | DJ10: =DJ21+DJ30+DJ48+DJ39+DJ57+DJ66 -> 360 | DK10: =DK21+DK30+DK48+DK39+DK57+DK66 -> 338 | DL10: =DL21+DL30+DL48+DL39+DL57+DL66 -> 318 | DM10: =DM21+DM30+DM48+DM39+DM57+DM66 -> 389 | DN10: =DN21+DN30+DN48+DN39+DN57+DN66 -> 541 | ... EJ10: =EJ21+EJ30+EJ48+EJ39+EJ57+EJ66 -> 399 | EK10: =SUM(EL10:FP10) -> 14458 | EL10: =EL21+EL30+EL48+EL39+EL57+EL66 -> 427 | EM10: =EM21+EM30+EM48+EM39+EM57+EM66 -> 396 | EN10: =EN21+EN30+EN48+EN39+EN57+EN66 -> 414 | EO10: =EO21+EO30+EO48+EO39+EO57+EO66 -> 408 | EP10: =EP21+EP30+EP48+EP39+EP57+EP66 -> 432 | EQ10: =EQ21+EQ30+EQ48+EQ39+EQ57+EQ66 -> 371 | ER10: =ER21+ER30+ER48+ER39+ER57+ER66 -> 348 | ES10: =ES21+ES30+ES48+ES39+ES57+ES66 -> 687 | ... FP10: =FP21+FP30+FP48+FP39+FP57+FP66 -> 540 | FQ10: =SUM(FR10:GX10) -> 8339 | FR10: =FR21+FR30+FR48+FR39+FR57+FR66 -> 361 | FS10: =FS21+FS30+FS48+FS39+FS57+FS66 -> 315 | FT10: =FT21+FT30+FT48+FT39+FT57+FT66 -> 295 | FU10: =FU21+FU30+FU48+FU39+FU57+FU66 -> 370 | FV10: =FV21+FV30+FV48+FV39+FV57+FV66 -> 356 | FW10: =FW21+FW30+FW48+FW39+FW57+FW66 -> 463 | FX10: =FX21+FX30+FX48+FX39+FX57+FX66 -> 523 | FY10: =FY21+FY30+FY48+FY39+FY57+FY66 -> 414 | ... GP10: =GP21+GP30+GP48+GP39+GP57+GP66 -> 0
A11: =D5 -> 39572.03 | C11: 点击单价 | D11: =D3/D10 -> #REF! | E11: =E3/E10 -> #REF! | F11: =F3/F10 -> #REF! | G11: =G3/G10 -> #REF! | H11: =H3/H10 -> #REF! | I11: =I3/I10 -> #REF! | J11: =J3/J10 -> #REF! | K11: =K3/K10 -> #REF! | ... GP11: =GP3/GP10 -> #DIV/0!
C12: 总购物车数 | D12: =SUM(E12:P12) -> #REF! | E12: =E22+E31+E40+E49+E58+E67 -> #REF! | F12: =F22+F31+F40+F49+F58+F67 -> #REF! | G12: =G22+G31+G40+G49+G58+G67 -> #REF! | H12: =H22+H31+H40+H49+H58+H67 -> #REF! | I12: =I22+I31+I40+I49+I58+I67 -> #REF! | J12: =J22+J31+J40+J49+J58+J67 -> #REF! | K12: =K22+K31+K40+K49+K58+K67 -> #REF! | L12: =L22+L31+L40+L49+L58+L67 -> #REF! | ... P12: =P22+P31+P40+P49+P58+P67 -> #REF! | Q12: =SUM(R12:AV12) -> 573 | R12: =R22+R31+R40+R49+R58+R67 -> 11 | S12: =S22+S31+S40+S49+S58+S67 -> 17 | T12: =T22+T31+T40+T49+T58+T67 -> 11 | U12: =U22+U31+U40+U49+U58+U67 -> 17 | V12: =V22+V31+V40+V49+V58+V67 -> 17 | W12: =W22+W31+W40+W49+W58+W67 -> 17 | X12: =X22+X31+X40+X49+X58+X67 -> 18 | Y12: =Y22+Y31+Y40+Y49+Y58+Y67 -> 20 | ... AV12: =AV22+AV31+AV40+AV49+AV58+AV67 -> 24 | AW12: =SUM(AX12:BY12) -> 518 | AX12: =AX22+AX31+AX40+AX49+AX58+AX67 -> 37 | AY12: =AY22+AY31+AY40+AY49+AY58+AY67 -> 17 | AZ12: =AZ22+AZ31+AZ40+AZ49+AZ58+AZ67 -> 23 | BA12: =BA22+BA31+BA40+BA49+BA58+BA67 -> 12 | BB12: =BB22+BB31+BB40+BB49+BB58+BB67 -> 19 | BC12: =BC22+BC31+BC40+BC49+BC58+BC67 -> 51 | BD12: =BD22+BD31+BD40+BD49+BD58+BD67 -> 25 | BE12: =BE22+BE31+BE40+BE49+BE58+BE67 -> 36 | ... BY12: =BY22+BY31+BY40+BY49+BY58+BY67 -> 15 | BZ12: =SUM(CA12:DE12) -> 938 | CA12: =CA22+CA31+CA40+CA49+CA58+CA67 -> 22 | CB12: =CB22+CB31+CB40+CB49+CB58+CB67 -> 17 | CC12: =CC22+CC31+CC40+CC49+CC58+CC67 -> 28 | CD12: =CD22+CD31+CD40+CD49+CD58+CD67 -> 25 | CE12: =CE22+CE31+CE40+CE49+CE58+CE67 -> 23 | CF12: =CF22+CF31+CF40+CF49+CF58+CF67 -> 11 | CG12: =CG22+CG31+CG40+CG49+CG58+CG67 -> 27 | CH12: =CH22+CH31+CH40+CH49+CH58+CH67 -> 69 | ... DE12: =DE22+DE31+DE40+DE49+DE58+DE67 -> 14 | DF12: =SUM(DG12:EJ12) -> 522 | DG12: =DG22+DG31+DG40+DG49+DG58+DG67 -> 10 | DH12: =DH22+DH31+DH40+DH49+DH58+DH67 -> 12 | DI12: =DI22+DI31+DI40+DI49+DI58+DI67 -> 10 | DJ12: =DJ22+DJ31+DJ40+DJ49+DJ58+DJ67 -> 9 | DK12: =DK22+DK31+DK40+DK49+DK58+DK67 -> 16 | DL12: =DL22+DL31+DL40+DL49+DL58+DL67 -> 15 | DM12: =DM22+DM31+DM40+DM49+DM58+DM67 -> 16 | DN12: =DN22+DN31+DN40+DN49+DN58+DN67 -> 23 | ... EJ12: =EJ22+EJ31+EJ40+EJ49+EJ58+EJ67 -> 15 | EK12: =SUM(EL12:FP12) -> 627 | EL12: =EL22+EL31+EL40+EL49+EL58+EL67 -> 18 | EM12: =EM22+EM31+EM40+EM49+EM58+EM67 -> 9 | EN12: =EN22+EN31+EN40+EN49+EN58+EN67 -> 13 | EO12: =EO22+EO31+EO40+EO49+EO58+EO67 -> 15 | EP12: =EP22+EP31+EP40+EP49+EP58+EP67 -> 35 | EQ12: =EQ22+EQ31+EQ40+EQ49+EQ58+EQ67 -> 19 | ER12: =ER22+ER31+ER40+ER49+ER58+ER67 -> 28 | ES12: =ES22+ES31+ES40+ES49+ES58+ES67 -> 15 | ... FP12: =FP22+FP31+FP40+FP49+FP58+FP67 -> 23 | FQ12: =SUM(FR12:GX12) -> 428 | FR12: =FR22+FR31+FR40+FR49+FR58+FR67 -> 12 | FS12: =FS22+FS31+FS40+FS49+FS58+FS67 -> 12 | FT12: =FT22+FT31+FT40+FT49+FT58+FT67 -> 20 | FU12: =FU22+FU31+FU40+FU49+FU58+FU67 -> 15 | FV12: =FV22+FV31+FV40+FV49+FV58+FV67 -> 15 | FW12: =FW22+FW31+FW40+FW49+FW58+FW67 -> 20 | FX12: =FX22+FX31+FX40+FX49+FX58+FX67 -> 32 | FY12: =FY22+FY31+FY40+FY49+FY58+FY67 -> 23 | ... GP12: =GP22+GP31+GP40+GP49+GP58+GP67 -> 0
C13: 加购成本 | D13: =D3/D12 -> #REF! | E13: =E3/E12 -> #REF! | F13: =F3/F12 -> #REF! | G13: =G3/G12 -> #REF! | H13: =H3/H12 -> #REF! | I13: =I3/I12 -> #REF! | J13: =J3/J12 -> #REF! | K13: =K3/K12 -> #REF! | ... GP13: =GP3/GP12 -> #DIV/0!
C14: 总成交量 | D14: =SUM(E14:P14) -> #REF! | E14: =E23+E32+E41+E50+E59+E68 -> #REF! | F14: =F23+F32+F41+F50+F59+F68 -> #REF! | G14: =G23+G32+G41+G50+G59+G68 -> #REF! | H14: =H23+H32+H41+H50+H59+H68 -> #REF! | I14: =I23+I32+I41+I50+I59+I68 -> #REF! | J14: =J23+J32+J41+J50+J59+J68 -> #REF! | K14: =K23+K32+K41+K50+K59+K68 -> #REF! | L14: =L23+L32+L41+L50+L59+L68 -> #REF! | ... P14: =P23+P32+P41+P50+P59+P68 -> #REF! | Q14: =SUM(R14:AV14) -> 123 | R14: =R23+R32+R41+R50+R59+R68 -> 2 | S14: =S23+S32+S41+S50+S59+S68 -> 3 | T14: =T23+T32+T41+T50+T59+T68 -> 2 | U14: =U23+U32+U41+U50+U59+U68 -> 10 | V14: =V23+V32+V41+V50+V59+V68 -> 2 | W14: =W23+W32+W41+W50+W59+W68 -> 3 | X14: =X23+X32+X41+X50+X59+X68 -> 2 | Y14: =Y23+Y32+Y41+Y50+Y59+Y68 -> 3 | ... AV14: =AV23+AV32+AV41+AV50+AV59+AV68 -> 5 | AW14: =SUM(AX14:BY14) -> 98 | AX14: =AX23+AX32+AX41+AX50+AX59+AX68 -> 7 | AY14: =AY23+AY32+AY41+AY50+AY59+AY68 -> 4 | AZ14: =AZ23+AZ32+AZ41+AZ50+AZ59+AZ68 -> 4 | BA14: =BA23+BA32+BA41+BA50+BA59+BA68 -> 8 | BB14: =BB23+BB32+BB41+BB50+BB59+BB68 -> 8 | BC14: =BC23+BC32+BC41+BC50+BC59+BC68 -> 16 | BD14: =BD23+BD32+BD41+BD50+BD59+BD68 -> 9 | BE14: =BE23+BE32+BE41+BE50+BE59+BE68 -> 5 | ... BY14: =BY23+BY32+BY41+BY50+BY59+BY68 -> 1 | BZ14: =SUM(CA14:DE14) -> 165 | CA14: =CA23+CA32+CA41+CA50+CA59+CA68 -> 4 | CB14: =CB23+CB32+CB41+CB50+CB59+CB68 -> 1 | CC14: =CC23+CC32+CC41+CC50+CC59+CC68 -> 4 | CD14: =CD23+CD32+CD41+CD50+CD59+CD68 -> 6 | CE14: =CE23+CE32+CE41+CE50+CE59+CE68 -> 4 | CF14: =CF23+CF32+CF41+CF50+CF59+CF68 -> 2 | CG14: =CG23+CG32+CG41+CG50+CG59+CG68 -> 3 | CH14: =CH23+CH32+CH41+CH50+CH59+CH68 -> 8 | ... DE14: =DE23+DE32+DE41+DE50+DE59+DE68 -> 5 | DF14: =SUM(DG14:EJ14) -> 137 | DG14: =DG23+DG32+DG41+DG50+DG59+DG68 -> 4 | DH14: =DH23+DH32+DH41+DH50+DH59+DH68 -> 3 | DI14: =DI23+DI32+DI41+DI50+DI59+DI68 -> 4 | DJ14: =DJ23+DJ32+DJ41+DJ50+DJ59+DJ68 -> 1 | DK14: =DK23+DK32+DK41+DK50+DK59+DK68 -> 6 | DL14: =DL23+DL32+DL41+DL50+DL59+DL68 -> 2 | DM14: =DM23+DM32+DM41+DM50+DM59+DM68 -> 7 | DN14: =DN23+DN32+DN41+DN50+DN59+DN68 -> 4 | ... EJ14: =EJ23+EJ32+EJ41+EJ50+EJ59+EJ68 -> 1 | EK14: =SUM(EL14:FP14) -> 128 | EL14: =EL23+EL32+EL41+EL50+EL59+EL68 -> 3 | EM14: =EM23+EM32+EM41+EM50+EM59+EM68 -> 1 | EN14: =EN23+EN32+EN41+EN50+EN59+EN68 -> 2 | EO14: =EO23+EO32+EO41+EO50+EO59+EO68 -> 0 | EP14: =EP23+EP32+EP41+EP50+EP59+EP68 -> 20 | EQ14: =EQ23+EQ32+EQ41+EQ50+EQ59+EQ68 -> 4 | ER14: =ER23+ER32+ER41+ER50+ER59+ER68 -> 2 | ES14: =ES23+ES32+ES41+ES50+ES59+ES68 -> 1 | ... FP14: =FP23+FP32+FP41+FP50+FP59+FP68 -> 1 | FQ14: =SUM(FR14:GX14) -> 105 | FR14: =FR23+FR32+FR41+FR50+FR59+FR68 -> 3 | FS14: =FS23+FS32+FS41+FS50+FS59+FS68 -> 5 | FT14: =FT23+FT32+FT41+FT50+FT59+FT68 -> 8 | FU14: =FU23+FU32+FU41+FU50+FU59+FU68 -> 6 | FV14: =FV23+FV32+FV41+FV50+FV59+FV68 -> 10 | FW14: =FW23+FW32+FW41+FW50+FW59+FW68 -> 7 | FX14: =FX23+FX32+FX41+FX50+FX59+FX68 -> 8 | FY14: =FY23+FY32+FY41+FY50+FY59+FY68 -> 7 | ... GP14: =GP23+GP32+GP41+GP50+GP59+GP68 -> 0
C15: 总成交金额 | D15: =SUM(E15:P15) -> #REF! | E15: =E24+E33+E42+E51+E60+E69 -> #REF! | F15: =F24+F33+F42+F51+F60+F69 -> #REF! | G15: =G24+G33+G42+G51+G60+G69 -> #REF! | H15: =H24+H33+H42+H51+H60+H69 -> #REF! | I15: =I24+I33+I42+I51+I60+I69 -> #REF! | J15: =J24+J33+J42+J51+J60+J69 -> #REF! | K15: =K24+K33+K42+K51+K60+K69 -> #REF! | L15: =L24+L33+L42+L51+L60+L69 -> #REF! | ... P15: =P24+P33+P42+P51+P60+P69 -> #REF! | Q15: =SUM(R15:AV15) -> 200211.68 | R15: =R24+R33+R42+R51+R60+R69 -> 617.1 | S15: =S24+S33+S42+S51+S60+S69 -> 401.91 | T15: =T24+T33+T42+T51+T60+T69 -> 96.9 | U15: =U24+U33+U42+U51+U60+U69 -> 6951.49 | V15: =V24+V33+V42+V51+V60+V69 -> 1793.4 | W15: =W24+W33+W42+W51+W60+W69 -> 1128 | X15: =X24+X33+X42+X51+X60+X69 -> 122.56 | Y15: =Y24+Y33+Y42+Y51+Y60+Y69 -> 2407.44 | ... AV15: =AV24+AV33+AV42+AV51+AV60+AV69 -> 1870.48 | AW15: =SUM(AX15:BY15) -> 39122.11 | AX15: =AX24+AX33+AX42+AX51+AX60+AX69 -> 8390.74 | AY15: =AY24+AY33+AY42+AY51+AY60+AY69 -> 2790.18 | AZ15: =AZ24+AZ33+AZ42+AZ51+AZ60+AZ69 -> 427.16 | BA15: =BA24+BA33+BA42+BA51+BA60+BA69 -> 5809.76 | BB15: =BB24+BB33+BB42+BB51+BB60+BB69 -> 3601.82 | BC15: =BC24+BC33+BC42+BC51+BC60+BC69 -> 2667.24 | BD15: =BD24+BD33+BD42+BD51+BD60+BD69 -> 1270.24 | BE15: =BE24+BE33+BE42+BE51+BE60+BE69 -> 826.81 | ... BY15: =BY24+BY33+BY42+BY51+BY60+BY69 -> 176 | BZ15: =SUM(CA15:DE15) -> 32451.21 | CA15: =CA24+CA33+CA42+CA51+CA60+CA69 -> 567.87 | CB15: =CB24+CB33+CB42+CB51+CB60+CB69 -> 236 | CC15: =CC24+CC33+CC42+CC51+CC60+CC69 -> 426.28 | CD15: =CD24+CD33+CD42+CD51+CD60+CD69 -> 3328.08 | CE15: =CE24+CE33+CE42+CE51+CE60+CE69 -> 1610.9 | CF15: =CF24+CF33+CF42+CF51+CF60+CF69 -> 1046.82 | CG15: =CG24+CG33+CG42+CG51+CG60+CG69 -> 320.4 | CH15: =CH24+CH33+CH42+CH51+CH60+CH69 -> 1211.17 | ... DE15: =DE24+DE33+DE42+DE51+DE60+DE69 -> 293.11 | DF15: =SUM(DG15:EJ15) -> 29052.16 | DG15: =DG24+DG33+DG42+DG51+DG60+DG69 -> 272.22 | DH15: =DH24+DH33+DH42+DH51+DH60+DH69 -> 333.54 | DI15: =DI24+DI33+DI42+DI51+DI60+DI69 -> 440.52 | DJ15: =DJ24+DJ33+DJ42+DJ51+DJ60+DJ69 -> 84.15 | DK15: =DK24+DK33+DK42+DK51+DK60+DK69 -> 1162.18 | DL15: =DL24+DL33+DL42+DL51+DL60+DL69 -> 194.9 | DM15: =DM24+DM33+DM42+DM51+DM60+DM69 -> 2210.48 | DN15: =DN24+DN33+DN42+DN51+DN60+DN69 -> 2936.93 | ... EJ15: =EJ24+EJ33+EJ42+EJ51+EJ60+EJ69 -> 85.12 | EK15: =SUM(EL15:FP15) -> 42473.03 | EL15: =EL24+EL33+EL42+EL51+EL60+EL69 -> 259.25 | EM15: =EM24+EM33+EM42+EM51+EM60+EM69 -> 151 | EN15: =EN24+EN33+EN42+EN51+EN60+EN69 -> 125.1 | EO15: =EO24+EO33+EO42+EO51+EO60+EO69 -> 0 | EP15: =EP24+EP33+EP42+EP51+EP60+EP69 -> 4676.39 | EQ15: =EQ24+EQ33+EQ42+EQ51+EQ60+EQ69 -> 1121.56 | ER15: =ER24+ER33+ER42+ER51+ER60+ER69 -> 8156.9 | ES15: =ES24+ES33+ES42+ES51+ES60+ES69 -> 81.13 | ... FP15: =FP24+FP33+FP42+FP51+FP60+FP69 -> 42.4 | FQ15: =SUM(FR15:GX15) -> 33318.12 | FR15: =FR24+FR33+FR42+FR51+FR60+FR69 -> 155.66 | FS15: =FS24+FS33+FS42+FS51+FS60+FS69 -> 389.31 | FT15: =FT24+FT33+FT42+FT51+FT60+FT69 -> 1615.04 | FU15: =FU24+FU33+FU42+FU51+FU60+FU69 -> 726.77 | FV15: =FV24+FV33+FV42+FV51+FV60+FV69 -> 18001.69 | FW15: =FW24+FW33+FW42+FW51+FW60+FW69 -> 424.26 | FX15: =FX24+FX33+FX42+FX51+FX60+FX69 -> 884.58 | FY15: =FY24+FY33+FY42+FY51+FY60+FY69 -> 841.6 | ... GP15: =GP24+GP33+GP42+GP51+GP60+GP69 -> 0
C16: 推广成交占比 | Q16: =Q15/Q5 -> 3.5462352 | R16: =R15/R5 -> 0.34342479 | S16: =S15/S5 -> 0.086849885 | T16: =T15/T5 -> 1.1936438 | U16: =U15/U5 -> 2.1933903 | V16: =V15/V5 -> 0.45585566 | W16: =W15/W5 -> 1.0792812 | X16: =X15/X5 -> 1.4116563 | ... GP16: =GP15/GP5 -> 0
C17: 加购率 | D17: =D12/D10 -> #REF! | E17: =E12/E10 -> #REF! | F17: =F12/F10 -> #REF! | G17: =G12/G10 -> #REF! | H17: =H12/H10 -> #REF! | I17: =I12/I10 -> #REF! | J17: =J12/J10 -> #REF! | K17: =K12/K10 -> #REF! | ... GP17: =GP12/GP10 -> #DIV/0!
C18: 点击转化率 | D18: =D14/D10 -> #REF! | Q18: =Q14/Q10 -> 0.019948102 | R18: =R14/R10 -> 0.013986014 | S18: =S14/S10 -> 0.015957447 | T18: =T14/T10 -> 0.0099502488 | U18: =U14/U10 -> 0.037878788 | V18: =V14/V10 -> 0.0081967213 | W18: =W14/W10 -> 0.015306122 | X18: =X14/X10 -> 0.0084033613 | ... GP18: =GP14/GP10 -> #DIV/0!
C19: 加购转化率 | D19: =D14/D12 -> #REF! | Q19: =Q14/Q12 -> 0.21465969 | R19: =R14/R12 -> 0.18181818 | S19: =S14/S12 -> 0.17647059 | T19: =T14/T12 -> 0.18181818 | U19: =U14/U12 -> 0.58823529 | V19: =V14/V12 -> 0.11764706 | W19: =W14/W12 -> 0.17647059 | X19: =X14/X12 -> 0.11111111 | ... GP19: =GP14/GP12 -> #DIV/0!
A20: 目标费率 | B20: 关键词推广 | C20: 花费 | D20: =SUM(E20:P20) -> #REF! | E20: =#REF! -> #REF! | F20: =#REF! -> #REF! | G20: =#REF! -> #REF! | H20: =#REF! -> #REF! | I20: =#REF! -> #REF! | J20: =#REF! -> #REF! | K20: =#REF! -> #REF! | L20: =#REF! -> #REF! | ... P20: =#REF! -> #REF! | Q20: =SUM(R20:AV20) -> 264.98 | R20: =SUMIFS(营销场景数据源!$H:$H,营销场景数据源!$C:$C,$B$20,营销场景数据源!$A:$A,R2) -> 0 | S20: =SUMIFS(营销场景数据源!$H:$H,营销场景数据源!$C:$C,$B$20,营销场景数据源!$A:$A,S2) -> 0 | T20: =SUMIFS(营销场景数据源!$H:$H,营销场景数据源!$C:$C,$B$20,营销场景数据源!$A:$A,T2) -> 0 | U20: =SUMIFS(营销场景数据源!$H:$H,营销场景数据源!$C:$C,$B$20,营销场景数据源!$A:$A,U2) -> 0 | V20: =SUMIFS(营销场景数据源!$H:$H,营销场景数据源!$C:$C,$B$20,营销场景数据源!$A:$A,V2) -> 0 | W20: =SUMIFS(营销场景数据源!$H:$H,营销场景数据源!$C:$C,$B$20,营销场景数据源!$A:$A,W2) -> 0 | X20: =SUMIFS(营销场景数据源!$H:$H,营销场景数据源!$C:$C,$B$20,营销场景数据源!$A:$A,X2) -> 0 | Y20: =SUMIFS(营销场景数据源!$H:$H,营销场景数据源!$C:$C,$B$20,营销场景数据源!$A:$A,Y2) -> 0 | ... AV20: =SUMIFS(营销场景数据源!$H:$H,营销场景数据源!$C:$C,$B$20,营销场景数据源!$A:$A,AV2) -> 12.05 | AW20: =SUM(AX20:BY20) -> 904.05 | AX20: =SUMIFS(营销场景数据源!$H:$H,营销场景数据源!$C:$C,$B$20,营销场景数据源!$A:$A,AX2) -> 19.92 | AY20: =SUMIFS(营销场景数据源!$H:$H,营销场景数据源!$C:$C,$B$20,营销场景数据源!$A:$A,AY2) -> 24.1 | AZ20: =SUMIFS(营销场景数据源!$H:$H,营销场景数据源!$C:$C,$B$20,营销场景数据源!$A:$A,AZ2) -> 31.76 | BA20: =SUMIFS(营销场景数据源!$H:$H,营销场景数据源!$C:$C,$B$20,营销场景数据源!$A:$A,BA2) -> 31.99 | BB20: =SUMIFS(营销场景数据源!$H:$H,营销场景数据源!$C:$C,$B$20,营销场景数据源!$A:$A,BB2) -> 29.14 | BC20: =SUMIFS(营销场景数据源!$H:$H,营销场景数据源!$C:$C,$B$20,营销场景数据源!$A:$A,BC2) -> 32.41 | BD20: =SUMIFS(营销场景数据源!$H:$H,营销场景数据源!$C:$C,$B$20,营销场景数据源!$A:$A,BD2) -> 25.39 | BE20: =SUMIFS(营销场景数据源!$H:$H,营销场景数据源!$C:$C,$B$20,营销场景数据源!$A:$A,BE2) -> 33.67 | ... BY20: =SUMIFS(营销场景数据源!$H:$H,营销场景数据源!$C:$C,$B$20,营销场景数据源!$A:$A,BY2) -> 32 | BZ20: =SUM(CA20:DE20) -> 1236.75 | CA20: =SUMIFS(营销场景数据源!$H:$H,营销场景数据源!$C:$C,$B$20,营销场景数据源!$A:$A,CA2) -> 32.18 | CB20: =SUMIFS(营销场景数据源!$H:$H,营销场景数据源!$C:$C,$B$20,营销场景数据源!$A:$A,CB2) -> 32.77 | CC20: =SUMIFS(营销场景数据源!$H:$H,营销场景数据源!$C:$C,$B$20,营销场景数据源!$A:$A,CC2) -> 26.16 | CD20: =SUMIFS(营销场景数据源!$H:$H,营销场景数据源!$C:$C,$B$20,营销场景数据源!$A:$A,CD2) -> 20.34 | CE20: =SUMIFS(营销场景数据源!$H:$H,营销场景数据源!$C:$C,$B$20,营销场景数据源!$A:$A,CE2) -> 50.75 | CF20: =SUMIFS(营销场景数据源!$H:$H,营销场景数据源!$C:$C,$B$20,营销场景数据源!$A:$A,CF2) -> 29.88 | CG20: =SUMIFS(营销场景数据源!$H:$H,营销场景数据源!$C:$C,$B$20,营销场景数据源!$A:$A,CG2) -> 30.01 | CH20: =SUMIFS(营销场景数据源!$H:$H,营销场景数据源!$C:$C,$B$20,营销场景数据源!$A:$A,CH2) -> 34.45 | ... DE20: =SUMIFS(营销场景数据源!$H:$H,营销场景数据源!$C:$C,$B$20,营销场景数据源!$A:$A,DE2) -> 58.54 | DF20: =SUM(DG20:EJ20) -> 1684.53 | DG20: =SUMIFS(营销场景数据源!$H:$H,营销场景数据源!$C:$C,$B$20,营销场景数据源!$A:$A,DG2) -> 59.72 | DH20: =SUMIFS(营销场景数据源!$H:$H,营销场景数据源!$C:$C,$B$20,营销场景数据源!$A:$A,DH2) -> 52.36 | DI20: =SUMIFS(营销场景数据源!$H:$H,营销场景数据源!$C:$C,$B$20,营销场景数据源!$A:$A,DI2) -> 59.53 | DJ20: =SUMIFS(营销场景数据源!$H:$H,营销场景数据源!$C:$C,$B$20,营销场景数据源!$A:$A,DJ2) -> 59.41 | DK20: =SUMIFS(营销场景数据源!$H:$H,营销场景数据源!$C:$C,$B$20,营销场景数据源!$A:$A,DK2) -> 59.33 | DL20: =SUMIFS(营销场景数据源!$H:$H,营销场景数据源!$C:$C,$B$20,营销场景数据源!$A:$A,DL2) -> 58.25 | DM20: =SUMIFS(营销场景数据源!$H:$H,营销场景数据源!$C:$C,$B$20,营销场景数据源!$A:$A,DM2) -> 58.46 | DN20: =SUMIFS(营销场景数据源!$H:$H,营销场景数据源!$C:$C,$B$20,营销场景数据源!$A:$A,DN2) -> 57.17 | ... EJ20: =SUMIFS(营销场景数据源!$H:$H,营销场景数据源!$C:$C,$B$20,营销场景数据源!$A:$A,EJ2) -> 21.1 | EK20: =SUM(EL20:FP20) -> 2319.42 | EL20: =SUMIFS(营销场景数据源!$H:$H,营销场景数据源!$C:$C,$B$20,营销场景数据源!$A:$A,EL2) -> 12.04 | EM20: =SUMIFS(营销场景数据源!$H:$H,营销场景数据源!$C:$C,$B$20,营销场景数据源!$A:$A,EM2) -> 11.76 | EN20: =SUMIFS(营销场景数据源!$H:$H,营销场景数据源!$C:$C,$B$20,营销场景数据源!$A:$A,EN2) -> 12.37 | EO20: =SUMIFS(营销场景数据源!$H:$H,营销场景数据源!$C:$C,$B$20,营销场景数据源!$A:$A,EO2) -> 12.16 | EP20: =SUMIFS(营销场景数据源!$H:$H,营销场景数据源!$C:$C,$B$20,营销场景数据源!$A:$A,EP2) -> 10.14 | EQ20: =SUMIFS(营销场景数据源!$H:$H,营销场景数据源!$C:$C,$B$20,营销场景数据源!$A:$A,EQ2) -> 20.71 | ER20: =SUMIFS(营销场景数据源!$H:$H,营销场景数据源!$C:$C,$B$20,营销场景数据源!$A:$A,ER2) -> 21.81 | ES20: =SUMIFS(营销场景数据源!$H:$H,营销场景数据源!$C:$C,$B$20,营销场景数据源!$A:$A,ES2) -> 19.64 | ... FP20: =SUMIFS(营销场景数据源!$H:$H,营销场景数据源!$C:$C,$B$20,营销场景数据源!$A:$A,FP2) -> 112.12 | FQ20: =SUM(FR20:GX20) -> 2486.34 | FR20: =SUMIFS(营销场景数据源!$H:$H,营销场景数据源!$C:$C,$B$20,营销场景数据源!$A:$A,FR2) -> 91.6 | FS20: =SUMIFS(营销场景数据源!$H:$H,营销场景数据源!$C:$C,$B$20,营销场景数据源!$A:$A,FS2) -> 85.51 | FT20: =SUMIFS(营销场景数据源!$H:$H,营销场景数据源!$C:$C,$B$20,营销场景数据源!$A:$A,FT2) -> 67.72 | FU20: =SUMIFS(营销场景数据源!$H:$H,营销场景数据源!$C:$C,$B$20,营销场景数据源!$A:$A,FU2) -> 111.06 | FV20: =SUMIFS(营销场景数据源!$H:$H,营销场景数据源!$C:$C,$B$20,营销场景数据源!$A:$A,FV2) -> 108.79 | FW20: =SUMIFS(营销场景数据源!$H:$H,营销场景数据源!$C:$C,$B$20,营销场景数据源!$A:$A,FW2) -> 105.42 | FX20: =SUMIFS(营销场景数据源!$H:$H,营销场景数据源!$C:$C,$B$20,营销场景数据源!$A:$A,FX2) -> 113.8 | FY20: =SUMIFS(营销场景数据源!$H:$H,营销场景数据源!$C:$C,$B$20,营销场景数据源!$A:$A,FY2) -> 137.03 | ... GP20: =SUMIFS(营销场景数据源!$H:$H,营销场景数据源!$C:$C,$B$20,营销场景数据源!$A:$A,GP2) -> 0
C21: 点击量 | D21: =SUM(E21:P21) -> #REF! | E21: =#REF! -> #REF! | F21: =#REF! -> #REF! | G21: =#REF! -> #REF! | H21: =#REF! -> #REF! | I21: =#REF! -> #REF! | J21: =#REF! -> #REF! | K21: =#REF! -> #REF! | L21: =#REF! -> #REF! | ... P21: =#REF! -> #REF! | Q21: =SUM(R21:AV21) -> 377 | R21: =SUMIFS(营销场景数据源!$G:$G,营销场景数据源!$C:$C,$B$20,营销场景数据源!$A:$A,R2) -> 0 | S21: =SUMIFS(营销场景数据源!$G:$G,营销场景数据源!$C:$C,$B$20,营销场景数据源!$A:$A,S2) -> 0 | T21: =SUMIFS(营销场景数据源!$G:$G,营销场景数据源!$C:$C,$B$20,营销场景数据源!$A:$A,T2) -> 0 | U21: =SUMIFS(营销场景数据源!$G:$G,营销场景数据源!$C:$C,$B$20,营销场景数据源!$A:$A,U2) -> 0 | V21: =SUMIFS(营销场景数据源!$G:$G,营销场景数据源!$C:$C,$B$20,营销场景数据源!$A:$A,V2) -> 0 | W21: =SUMIFS(营销场景数据源!$G:$G,营销场景数据源!$C:$C,$B$20,营销场景数据源!$A:$A,W2) -> 0 | X21: =SUMIFS(营销场景数据源!$G:$G,营销场景数据源!$C:$C,$B$20,营销场景数据源!$A:$A,X2) -> 0 | Y21: =SUMIFS(营销场景数据源!$G:$G,营销场景数据源!$C:$C,$B$20,营销场景数据源!$A:$A,Y2) -> 0 | ... AV21: =SUMIFS(营销场景数据源!$G:$G,营销场景数据源!$C:$C,$B$20,营销场景数据源!$A:$A,AV2) -> 44 | AW21: =SUM(AX21:BY21) -> 3059 | AX21: =SUMIFS(营销场景数据源!$G:$G,营销场景数据源!$C:$C,$B$20,营销场景数据源!$A:$A,AX2) -> 70 | AY21: =SUMIFS(营销场景数据源!$G:$G,营销场景数据源!$C:$C,$B$20,营销场景数据源!$A:$A,AY2) -> 83 | AZ21: =SUMIFS(营销场景数据源!$G:$G,营销场景数据源!$C:$C,$B$20,营销场景数据源!$A:$A,AZ2) -> 91 | BA21: =SUMIFS(营销场景数据源!$G:$G,营销场景数据源!$C:$C,$B$20,营销场景数据源!$A:$A,BA2) -> 95 | BB21: =SUMIFS(营销场景数据源!$G:$G,营销场景数据源!$C:$C,$B$20,营销场景数据源!$A:$A,BB2) -> 93 | BC21: =SUMIFS(营销场景数据源!$G:$G,营销场景数据源!$C:$C,$B$20,营销场景数据源!$A:$A,BC2) -> 100 | BD21: =SUMIFS(营销场景数据源!$G:$G,营销场景数据源!$C:$C,$B$20,营销场景数据源!$A:$A,BD2) -> 82 | BE21: =SUMIFS(营销场景数据源!$G:$G,营销场景数据源!$C:$C,$B$20,营销场景数据源!$A:$A,BE2) -> 107 | ... BY21: =SUMIFS(营销场景数据源!$G:$G,营销场景数据源!$C:$C,$B$20,营销场景数据源!$A:$A,BY2) -> 124 | BZ21: =SUM(CA21:DE21) -> 4069 | CA21: =SUMIFS(营销场景数据源!$G:$G,营销场景数据源!$C:$C,$B$20,营销场景数据源!$A:$A,CA2) -> 127 | CB21: =SUMIFS(营销场景数据源!$G:$G,营销场景数据源!$C:$C,$B$20,营销场景数据源!$A:$A,CB2) -> 123 | CC21: =SUMIFS(营销场景数据源!$G:$G,营销场景数据源!$C:$C,$B$20,营销场景数据源!$A:$A,CC2) -> 106 | CD21: =SUMIFS(营销场景数据源!$G:$G,营销场景数据源!$C:$C,$B$20,营销场景数据源!$A:$A,CD2) -> 84 | CE21: =SUMIFS(营销场景数据源!$G:$G,营销场景数据源!$C:$C,$B$20,营销场景数据源!$A:$A,CE2) -> 154 | CF21: =SUMIFS(营销场景数据源!$G:$G,营销场景数据源!$C:$C,$B$20,营销场景数据源!$A:$A,CF2) -> 98 | CG21: =SUMIFS(营销场景数据源!$G:$G,营销场景数据源!$C:$C,$B$20,营销场景数据源!$A:$A,CG2) -> 104 | CH21: =SUMIFS(营销场景数据源!$G:$G,营销场景数据源!$C:$C,$B$20,营销场景数据源!$A:$A,CH2) -> 119 | ... DE21: =SUMIFS(营销场景数据源!$G:$G,营销场景数据源!$C:$C,$B$20,营销场景数据源!$A:$A,DE2) -> 199 | DF21: =SUM(DG21:EJ21) -> 4853 | DG21: =SUMIFS(营销场景数据源!$G:$G,营销场景数据源!$C:$C,$B$20,营销场景数据源!$A:$A,DG2) -> 237 | DH21: =SUMIFS(营销场景数据源!$G:$G,营销场景数据源!$C:$C,$B$20,营销场景数据源!$A:$A,DH2) -> 215 | DI21: =SUMIFS(营销场景数据源!$G:$G,营销场景数据源!$C:$C,$B$20,营销场景数据源!$A:$A,DI2) -> 222 | DJ21: =SUMIFS(营销场景数据源!$G:$G,营销场景数据源!$C:$C,$B$20,营销场景数据源!$A:$A,DJ2) -> 208 | DK21: =SUMIFS(营销场景数据源!$G:$G,营销场景数据源!$C:$C,$B$20,营销场景数据源!$A:$A,DK2) -> 183 | DL21: =SUMIFS(营销场景数据源!$G:$G,营销场景数据源!$C:$C,$B$20,营销场景数据源!$A:$A,DL2) -> 174 | DM21: =SUMIFS(营销场景数据源!$G:$G,营销场景数据源!$C:$C,$B$20,营销场景数据源!$A:$A,DM2) -> 171 | DN21: =SUMIFS(营销场景数据源!$G:$G,营销场景数据源!$C:$C,$B$20,营销场景数据源!$A:$A,DN2) -> 181 | ... EJ21: =SUMIFS(营销场景数据源!$G:$G,营销场景数据源!$C:$C,$B$20,营销场景数据源!$A:$A,EJ2) -> 71 | EK21: =SUM(EL21:FP21) -> 4180 | EL21: =SUMIFS(营销场景数据源!$G:$G,营销场景数据源!$C:$C,$B$20,营销场景数据源!$A:$A,EL2) -> 38 | EM21: =SUMIFS(营销场景数据源!$G:$G,营销场景数据源!$C:$C,$B$20,营销场景数据源!$A:$A,EM2) -> 35 | EN21: =SUMIFS(营销场景数据源!$G:$G,营销场景数据源!$C:$C,$B$20,营销场景数据源!$A:$A,EN2) -> 32 | EO21: =SUMIFS(营销场景数据源!$G:$G,营销场景数据源!$C:$C,$B$20,营销场景数据源!$A:$A,EO2) -> 33 | EP21: =SUMIFS(营销场景数据源!$G:$G,营销场景数据源!$C:$C,$B$20,营销场景数据源!$A:$A,EP2) -> 31 | EQ21: =SUMIFS(营销场景数据源!$G:$G,营销场景数据源!$C:$C,$B$20,营销场景数据源!$A:$A,EQ2) -> 48 | ER21: =SUMIFS(营销场景数据源!$G:$G,营销场景数据源!$C:$C,$B$20,营销场景数据源!$A:$A,ER2) -> 53 | ES21: =SUMIFS(营销场景数据源!$G:$G,营销场景数据源!$C:$C,$B$20,营销场景数据源!$A:$A,ES2) -> 39 | ... FP21: =SUMIFS(营销场景数据源!$G:$G,营销场景数据源!$C:$C,$B$20,营销场景数据源!$A:$A,FP2) -> 258 | FQ21: =SUM(FR21:GX21) -> 3583 | FR21: =SUMIFS(营销场景数据源!$G:$G,营销场景数据源!$C:$C,$B$20,营销场景数据源!$A:$A,FR2) -> 163 | FS21: =SUMIFS(营销场景数据源!$G:$G,营销场景数据源!$C:$C,$B$20,营销场景数据源!$A:$A,FS2) -> 134 | FT21: =SUMIFS(营销场景数据源!$G:$G,营销场景数据源!$C:$C,$B$20,营销场景数据源!$A:$A,FT2) -> 102 | FU21: =SUMIFS(营销场景数据源!$G:$G,营销场景数据源!$C:$C,$B$20,营销场景数据源!$A:$A,FU2) -> 191 | FV21: =SUMIFS(营销场景数据源!$G:$G,营销场景数据源!$C:$C,$B$20,营销场景数据源!$A:$A,FV2) -> 176 | FW21: =SUMIFS(营销场景数据源!$G:$G,营销场景数据源!$C:$C,$B$20,营销场景数据源!$A:$A,FW2) -> 160 | FX21: =SUMIFS(营销场景数据源!$G:$G,营销场景数据源!$C:$C,$B$20,营销场景数据源!$A:$A,FX2) -> 174 | FY21: =SUMIFS(营销场景数据源!$G:$G,营销场景数据源!$C:$C,$B$20,营销场景数据源!$A:$A,FY2) -> 183 | ... GP21: =SUMIFS(营销场景数据源!$G:$G,营销场景数据源!$C:$C,$B$20,营销场景数据源!$A:$A,GP2) -> 0
A22: 实际费率 | C22: 总购物车数 | D22: =SUM(E22:P22) -> #REF! | E22: =#REF! -> #REF! | F22: =#REF! -> #REF! | G22: =#REF! -> #REF! | H22: =#REF! -> #REF! | I22: =#REF! -> #REF! | J22: =#REF! -> #REF! | K22: =#REF! -> #REF! | L22: =#REF! -> #REF! | ... P22: =#REF! -> #REF! | Q22: =SUM(R22:AV22) -> 10 | R22: =SUMIFS(营销场景数据源!$AB:$AB,营销场景数据源!$C:$C,$B$20,营销场景数据源!$A:$A,R2) -> 0 | S22: =SUMIFS(营销场景数据源!$AB:$AB,营销场景数据源!$C:$C,$B$20,营销场景数据源!$A:$A,S2) -> 0 | T22: =SUMIFS(营销场景数据源!$AB:$AB,营销场景数据源!$C:$C,$B$20,营销场景数据源!$A:$A,T2) -> 0 | U22: =SUMIFS(营销场景数据源!$AB:$AB,营销场景数据源!$C:$C,$B$20,营销场景数据源!$A:$A,U2) -> 0 | V22: =SUMIFS(营销场景数据源!$AB:$AB,营销场景数据源!$C:$C,$B$20,营销场景数据源!$A:$A,V2) -> 0 | W22: =SUMIFS(营销场景数据源!$AB:$AB,营销场景数据源!$C:$C,$B$20,营销场景数据源!$A:$A,W2) -> 0 | X22: =SUMIFS(营销场景数据源!$AB:$AB,营销场景数据源!$C:$C,$B$20,营销场景数据源!$A:$A,X2) -> 0 | Y22: =SUMIFS(营销场景数据源!$AB:$AB,营销场景数据源!$C:$C,$B$20,营销场景数据源!$A:$A,Y2) -> 0 | ... AV22: =SUMIFS(营销场景数据源!$AB:$AB,营销场景数据源!$C:$C,$B$20,营销场景数据源!$A:$A,AV2) -> 0 | AW22: =SUM(AX22:BY22) -> 81 | AX22: =SUMIFS(营销场景数据源!$AB:$AB,营销场景数据源!$C:$C,$B$20,营销场景数据源!$A:$A,AX2) -> 3 | AY22: =SUMIFS(营销场景数据源!$AB:$AB,营销场景数据源!$C:$C,$B$20,营销场景数据源!$A:$A,AY2) -> 2 | AZ22: =SUMIFS(营销场景数据源!$AB:$AB,营销场景数据源!$C:$C,$B$20,营销场景数据源!$A:$A,AZ2) -> 0 | BA22: =SUMIFS(营销场景数据源!$AB:$AB,营销场景数据源!$C:$C,$B$20,营销场景数据源!$A:$A,BA2) -> 0 | BB22: =SUMIFS(营销场景数据源!$AB:$AB,营销场景数据源!$C:$C,$B$20,营销场景数据源!$A:$A,BB2) -> 2 | BC22: =SUMIFS(营销场景数据源!$AB:$AB,营销场景数据源!$C:$C,$B$20,营销场景数据源!$A:$A,BC2) -> 7 | BD22: =SUMIFS(营销场景数据源!$AB:$AB,营销场景数据源!$C:$C,$B$20,营销场景数据源!$A:$A,BD2) -> 0 | BE22: =SUMIFS(营销场景数据源!$AB:$AB,营销场景数据源!$C:$C,$B$20,营销场景数据源!$A:$A,BE2) -> 3 | ... BY22: =SUMIFS(营销场景数据源!$AB:$AB,营销场景数据源!$C:$C,$B$20,营销场景数据源!$A:$A,BY2) -> 1 | BZ22: =SUM(CA22:DE22) -> 95 | CA22: =SUMIFS(营销场景数据源!$AB:$AB,营销场景数据源!$C:$C,$B$20,营销场景数据源!$A:$A,CA2) -> 1 | CB22: =SUMIFS(营销场景数据源!$AB:$AB,营销场景数据源!$C:$C,$B$20,营销场景数据源!$A:$A,CB2) -> 2 | CC22: =SUMIFS(营销场景数据源!$AB:$AB,营销场景数据源!$C:$C,$B$20,营销场景数据源!$A:$A,CC2) -> 9 | CD22: =SUMIFS(营销场景数据源!$AB:$AB,营销场景数据源!$C:$C,$B$20,营销场景数据源!$A:$A,CD2) -> 1 | CE22: =SUMIFS(营销场景数据源!$AB:$AB,营销场景数据源!$C:$C,$B$20,营销场景数据源!$A:$A,CE2) -> 6 | CF22: =SUMIFS(营销场景数据源!$AB:$AB,营销场景数据源!$C:$C,$B$20,营销场景数据源!$A:$A,CF2) -> 0 | CG22: =SUMIFS(营销场景数据源!$AB:$AB,营销场景数据源!$C:$C,$B$20,营销场景数据源!$A:$A,CG2) -> 1 | CH22: =SUMIFS(营销场景数据源!$AB:$AB,营销场景数据源!$C:$C,$B$20,营销场景数据源!$A:$A,CH2) -> 12 | ... DE22: =SUMIFS(营销场景数据源!$AB:$AB,营销场景数据源!$C:$C,$B$20,营销场景数据源!$A:$A,DE2) -> 1 | DF22: =SUM(DG22:EJ22) -> 91 | DG22: =SUMIFS(营销场景数据源!$AB:$AB,营销场景数据源!$C:$C,$B$20,营销场景数据源!$A:$A,DG2) -> 2 | DH22: =SUMIFS(营销场景数据源!$AB:$AB,营销场景数据源!$C:$C,$B$20,营销场景数据源!$A:$A,DH2) -> 4 | DI22: =SUMIFS(营销场景数据源!$AB:$AB,营销场景数据源!$C:$C,$B$20,营销场景数据源!$A:$A,DI2) -> 2 | DJ22: =SUMIFS(营销场景数据源!$AB:$AB,营销场景数据源!$C:$C,$B$20,营销场景数据源!$A:$A,DJ2) -> 0 | DK22: =SUMIFS(营销场景数据源!$AB:$AB,营销场景数据源!$C:$C,$B$20,营销场景数据源!$A:$A,DK2) -> 0 | DL22: =SUMIFS(营销场景数据源!$AB:$AB,营销场景数据源!$C:$C,$B$20,营销场景数据源!$A:$A,DL2) -> 1 | DM22: =SUMIFS(营销场景数据源!$AB:$AB,营销场景数据源!$C:$C,$B$20,营销场景数据源!$A:$A,DM2) -> 0 | DN22: =SUMIFS(营销场景数据源!$AB:$AB,营销场景数据源!$C:$C,$B$20,营销场景数据源!$A:$A,DN2) -> 0 | ... EJ22: =SUMIFS(营销场景数据源!$AB:$AB,营销场景数据源!$C:$C,$B$20,营销场景数据源!$A:$A,EJ2) -> 1 | EK22: =SUM(EL22:FP22) -> 128 | EL22: =SUMIFS(营销场景数据源!$AB:$AB,营销场景数据源!$C:$C,$B$20,营销场景数据源!$A:$A,EL2) -> 3 | EM22: =SUMIFS(营销场景数据源!$AB:$AB,营销场景数据源!$C:$C,$B$20,营销场景数据源!$A:$A,EM2) -> 2 | EN22: =SUMIFS(营销场景数据源!$AB:$AB,营销场景数据源!$C:$C,$B$20,营销场景数据源!$A:$A,EN2) -> 1 | EO22: =SUMIFS(营销场景数据源!$AB:$AB,营销场景数据源!$C:$C,$B$20,营销场景数据源!$A:$A,EO2) -> 2 | EP22: =SUMIFS(营销场景数据源!$AB:$AB,营销场景数据源!$C:$C,$B$20,营销场景数据源!$A:$A,EP2) -> 3 | EQ22: =SUMIFS(营销场景数据源!$AB:$AB,营销场景数据源!$C:$C,$B$20,营销场景数据源!$A:$A,EQ2) -> 4 | ER22: =SUMIFS(营销场景数据源!$AB:$AB,营销场景数据源!$C:$C,$B$20,营销场景数据源!$A:$A,ER2) -> 6 | ES22: =SUMIFS(营销场景数据源!$AB:$AB,营销场景数据源!$C:$C,$B$20,营销场景数据源!$A:$A,ES2) -> 2 | ... FP22: =SUMIFS(营销场景数据源!$AB:$AB,营销场景数据源!$C:$C,$B$20,营销场景数据源!$A:$A,FP2) -> 2 | FQ22: =SUM(FR22:GX22) -> 119 | FR22: =SUMIFS(营销场景数据源!$AB:$AB,营销场景数据源!$C:$C,$B$20,营销场景数据源!$A:$A,FR2) -> 1 | FS22: =SUMIFS(营销场景数据源!$AB:$AB,营销场景数据源!$C:$C,$B$20,营销场景数据源!$A:$A,FS2) -> 2 | FT22: =SUMIFS(营销场景数据源!$AB:$AB,营销场景数据源!$C:$C,$B$20,营销场景数据源!$A:$A,FT2) -> 9 | FU22: =SUMIFS(营销场景数据源!$AB:$AB,营销场景数据源!$C:$C,$B$20,营销场景数据源!$A:$A,FU2) -> 2 | FV22: =SUMIFS(营销场景数据源!$AB:$AB,营销场景数据源!$C:$C,$B$20,营销场景数据源!$A:$A,FV2) -> 1 | FW22: =SUMIFS(营销场景数据源!$AB:$AB,营销场景数据源!$C:$C,$B$20,营销场景数据源!$A:$A,FW2) -> 9 | FX22: =SUMIFS(营销场景数据源!$AB:$AB,营销场景数据源!$C:$C,$B$20,营销场景数据源!$A:$A,FX2) -> 10 | FY22: =SUMIFS(营销场景数据源!$AB:$AB,营销场景数据源!$C:$C,$B$20,营销场景数据源!$A:$A,FY2) -> 6 | ... GP22: =SUMIFS(营销场景数据源!$AB:$AB,营销场景数据源!$C:$C,$B$20,营销场景数据源!$A:$A,GP2) -> 0
A23: =D6 -> #REF! | C23: 总成交量 | D23: =SUM(E23:P23) -> #REF! | E23: =#REF! -> #REF! | F23: =#REF! -> #REF! | G23: =#REF! -> #REF! | H23: =#REF! -> #REF! | I23: =#REF! -> #REF! | J23: =#REF! -> #REF! | K23: =#REF! -> #REF! | L23: =#REF! -> #REF! | ... P23: =#REF! -> #REF! | Q23: =SUM(R23:AV23) -> 0 | R23: =SUMIFS(营销场景数据源!$U:$U,营销场景数据源!$C:$C,$B$20,营销场景数据源!$A:$A,R2) -> 0 | S23: =SUMIFS(营销场景数据源!$U:$U,营销场景数据源!$C:$C,$B$20,营销场景数据源!$A:$A,S2) -> 0 | T23: =SUMIFS(营销场景数据源!$U:$U,营销场景数据源!$C:$C,$B$20,营销场景数据源!$A:$A,T2) -> 0 | U23: =SUMIFS(营销场景数据源!$U:$U,营销场景数据源!$C:$C,$B$20,营销场景数据源!$A:$A,U2) -> 0 | V23: =SUMIFS(营销场景数据源!$U:$U,营销场景数据源!$C:$C,$B$20,营销场景数据源!$A:$A,V2) -> 0 | W23: =SUMIFS(营销场景数据源!$U:$U,营销场景数据源!$C:$C,$B$20,营销场景数据源!$A:$A,W2) -> 0 | X23: =SUMIFS(营销场景数据源!$U:$U,营销场景数据源!$C:$C,$B$20,营销场景数据源!$A:$A,X2) -> 0 | Y23: =SUMIFS(营销场景数据源!$U:$U,营销场景数据源!$C:$C,$B$20,营销场景数据源!$A:$A,Y2) -> 0 | ... AV23: =SUMIFS(营销场景数据源!$U:$U,营销场景数据源!$C:$C,$B$20,营销场景数据源!$A:$A,AV2) -> 0 | AW23: =SUM(AX23:BY23) -> 10 | AX23: =SUMIFS(营销场景数据源!$U:$U,营销场景数据源!$C:$C,$B$20,营销场景数据源!$A:$A,AX2) -> 3 | AY23: =SUMIFS(营销场景数据源!$U:$U,营销场景数据源!$C:$C,$B$20,营销场景数据源!$A:$A,AY2) -> 2 | AZ23: =SUMIFS(营销场景数据源!$U:$U,营销场景数据源!$C:$C,$B$20,营销场景数据源!$A:$A,AZ2) -> 0 | BA23: =SUMIFS(营销场景数据源!$U:$U,营销场景数据源!$C:$C,$B$20,营销场景数据源!$A:$A,BA2) -> 0 | BB23: =SUMIFS(营销场景数据源!$U:$U,营销场景数据源!$C:$C,$B$20,营销场景数据源!$A:$A,BB2) -> 0 | BC23: =SUMIFS(营销场景数据源!$U:$U,营销场景数据源!$C:$C,$B$20,营销场景数据源!$A:$A,BC2) -> 2 | BD23: =SUMIFS(营销场景数据源!$U:$U,营销场景数据源!$C:$C,$B$20,营销场景数据源!$A:$A,BD2) -> 0 | BE23: =SUMIFS(营销场景数据源!$U:$U,营销场景数据源!$C:$C,$B$20,营销场景数据源!$A:$A,BE2) -> 0 | ... BY23: =SUMIFS(营销场景数据源!$U:$U,营销场景数据源!$C:$C,$B$20,营销场景数据源!$A:$A,BY2) -> 0 | BZ23: =SUM(CA23:DE23) -> 8 | CA23: =SUMIFS(营销场景数据源!$U:$U,营销场景数据源!$C:$C,$B$20,营销场景数据源!$A:$A,CA2) -> 0 | CB23: =SUMIFS(营销场景数据源!$U:$U,营销场景数据源!$C:$C,$B$20,营销场景数据源!$A:$A,CB2) -> 0 | CC23: =SUMIFS(营销场景数据源!$U:$U,营销场景数据源!$C:$C,$B$20,营销场景数据源!$A:$A,CC2) -> 0 | CD23: =SUMIFS(营销场景数据源!$U:$U,营销场景数据源!$C:$C,$B$20,营销场景数据源!$A:$A,CD2) -> 1 | CE23: =SUMIFS(营销场景数据源!$U:$U,营销场景数据源!$C:$C,$B$20,营销场景数据源!$A:$A,CE2) -> 2 | CF23: =SUMIFS(营销场景数据源!$U:$U,营销场景数据源!$C:$C,$B$20,营销场景数据源!$A:$A,CF2) -> 0 | CG23: =SUMIFS(营销场景数据源!$U:$U,营销场景数据源!$C:$C,$B$20,营销场景数据源!$A:$A,CG2) -> 0 | CH23: =SUMIFS(营销场景数据源!$U:$U,营销场景数据源!$C:$C,$B$20,营销场景数据源!$A:$A,CH2) -> 0 | ... DE23: =SUMIFS(营销场景数据源!$U:$U,营销场景数据源!$C:$C,$B$20,营销场景数据源!$A:$A,DE2) -> 0 | DF23: =SUM(DG23:EJ23) -> 14 | DG23: =SUMIFS(营销场景数据源!$U:$U,营销场景数据源!$C:$C,$B$20,营销场景数据源!$A:$A,DG2) -> 0 | DH23: =SUMIFS(营销场景数据源!$U:$U,营销场景数据源!$C:$C,$B$20,营销场景数据源!$A:$A,DH2) -> 0 | DI23: =SUMIFS(营销场景数据源!$U:$U,营销场景数据源!$C:$C,$B$20,营销场景数据源!$A:$A,DI2) -> 0 | DJ23: =SUMIFS(营销场景数据源!$U:$U,营销场景数据源!$C:$C,$B$20,营销场景数据源!$A:$A,DJ2) -> 0 | DK23: =SUMIFS(营销场景数据源!$U:$U,营销场景数据源!$C:$C,$B$20,营销场景数据源!$A:$A,DK2) -> 0 | DL23: =SUMIFS(营销场景数据源!$U:$U,营销场景数据源!$C:$C,$B$20,营销场景数据源!$A:$A,DL2) -> 0 | DM23: =SUMIFS(营销场景数据源!$U:$U,营销场景数据源!$C:$C,$B$20,营销场景数据源!$A:$A,DM2) -> 0 | DN23: =SUMIFS(营销场景数据源!$U:$U,营销场景数据源!$C:$C,$B$20,营销场景数据源!$A:$A,DN2) -> 0 | ... EJ23: =SUMIFS(营销场景数据源!$U:$U,营销场景数据源!$C:$C,$B$20,营销场景数据源!$A:$A,EJ2) -> 0 | EK23: =SUM(EL23:FP23) -> 25 | EL23: =SUMIFS(营销场景数据源!$U:$U,营销场景数据源!$C:$C,$B$20,营销场景数据源!$A:$A,EL2) -> 0 | EM23: =SUMIFS(营销场景数据源!$U:$U,营销场景数据源!$C:$C,$B$20,营销场景数据源!$A:$A,EM2) -> 1 | EN23: =SUMIFS(营销场景数据源!$U:$U,营销场景数据源!$C:$C,$B$20,营销场景数据源!$A:$A,EN2) -> 0 | EO23: =SUMIFS(营销场景数据源!$U:$U,营销场景数据源!$C:$C,$B$20,营销场景数据源!$A:$A,EO2) -> 0 | EP23: =SUMIFS(营销场景数据源!$U:$U,营销场景数据源!$C:$C,$B$20,营销场景数据源!$A:$A,EP2) -> 0 | EQ23: =SUMIFS(营销场景数据源!$U:$U,营销场景数据源!$C:$C,$B$20,营销场景数据源!$A:$A,EQ2) -> 1 | ER23: =SUMIFS(营销场景数据源!$U:$U,营销场景数据源!$C:$C,$B$20,营销场景数据源!$A:$A,ER2) -> 1 | ES23: =SUMIFS(营销场景数据源!$U:$U,营销场景数据源!$C:$C,$B$20,营销场景数据源!$A:$A,ES2) -> 0 | ... FP23: =SUMIFS(营销场景数据源!$U:$U,营销场景数据源!$C:$C,$B$20,营销场景数据源!$A:$A,FP2) -> 0 | FQ23: =SUM(FR23:GX23) -> 30 | FR23: =SUMIFS(营销场景数据源!$U:$U,营销场景数据源!$C:$C,$B$20,营销场景数据源!$A:$A,FR2) -> 1 | FS23: =SUMIFS(营销场景数据源!$U:$U,营销场景数据源!$C:$C,$B$20,营销场景数据源!$A:$A,FS2) -> 2 | FT23: =SUMIFS(营销场景数据源!$U:$U,营销场景数据源!$C:$C,$B$20,营销场景数据源!$A:$A,FT2) -> 4 | FU23: =SUMIFS(营销场景数据源!$U:$U,营销场景数据源!$C:$C,$B$20,营销场景数据源!$A:$A,FU2) -> 0 | FV23: =SUMIFS(营销场景数据源!$U:$U,营销场景数据源!$C:$C,$B$20,营销场景数据源!$A:$A,FV2) -> 0 | FW23: =SUMIFS(营销场景数据源!$U:$U,营销场景数据源!$C:$C,$B$20,营销场景数据源!$A:$A,FW2) -> 3 | FX23: =SUMIFS(营销场景数据源!$U:$U,营销场景数据源!$C:$C,$B$20,营销场景数据源!$A:$A,FX2) -> 3 | FY23: =SUMIFS(营销场景数据源!$U:$U,营销场景数据源!$C:$C,$B$20,营销场景数据源!$A:$A,FY2) -> 3 | ... GP23: =SUMIFS(营销场景数据源!$U:$U,营销场景数据源!$C:$C,$B$20,营销场景数据源!$A:$A,GP2) -> 0
A24: 目标销售占比 | C24: 总成交金额 | D24: =SUM(E24:P24) -> #REF! | E24: =#REF! -> #REF! | F24: =#REF! -> #REF! | G24: =#REF! -> #REF! | H24: =#REF! -> #REF! | I24: =#REF! -> #REF! | J24: =#REF! -> #REF! | K24: =#REF! -> #REF! | L24: =#REF! -> #REF! | ... P24: =#REF! -> #REF! | Q24: =SUM(R24:AV24) -> 0 | R24: =SUMIFS(营销场景数据源!$T:$T,营销场景数据源!$C:$C,$B$20,营销场景数据源!$A:$A,R2) -> 0 | S24: =SUMIFS(营销场景数据源!$T:$T,营销场景数据源!$C:$C,$B$20,营销场景数据源!$A:$A,S2) -> 0 | T24: =SUMIFS(营销场景数据源!$T:$T,营销场景数据源!$C:$C,$B$20,营销场景数据源!$A:$A,T2) -> 0 | U24: =SUMIFS(营销场景数据源!$T:$T,营销场景数据源!$C:$C,$B$20,营销场景数据源!$A:$A,U2) -> 0 | V24: =SUMIFS(营销场景数据源!$T:$T,营销场景数据源!$C:$C,$B$20,营销场景数据源!$A:$A,V2) -> 0 | W24: =SUMIFS(营销场景数据源!$T:$T,营销场景数据源!$C:$C,$B$20,营销场景数据源!$A:$A,W2) -> 0 | X24: =SUMIFS(营销场景数据源!$T:$T,营销场景数据源!$C:$C,$B$20,营销场景数据源!$A:$A,X2) -> 0 | Y24: =SUMIFS(营销场景数据源!$T:$T,营销场景数据源!$C:$C,$B$20,营销场景数据源!$A:$A,Y2) -> 0 | ... AV24: =SUMIFS(营销场景数据源!$T:$T,营销场景数据源!$C:$C,$B$20,营销场景数据源!$A:$A,AV2) -> 0 | AW24: =SUM(AX24:BY24) -> 9369.48 | AX24: =SUMIFS(营销场景数据源!$T:$T,营销场景数据源!$C:$C,$B$20,营销场景数据源!$A:$A,AX2) -> 5612.15 | AY24: =SUMIFS(营销场景数据源!$T:$T,营销场景数据源!$C:$C,$B$20,营销场景数据源!$A:$A,AY2) -> 2358.18 | AZ24: =SUMIFS(营销场景数据源!$T:$T,营销场景数据源!$C:$C,$B$20,营销场景数据源!$A:$A,AZ2) -> 0 | BA24: =SUMIFS(营销场景数据源!$T:$T,营销场景数据源!$C:$C,$B$20,营销场景数据源!$A:$A,BA2) -> 0 | BB24: =SUMIFS(营销场景数据源!$T:$T,营销场景数据源!$C:$C,$B$20,营销场景数据源!$A:$A,BB2) -> 0 | BC24: =SUMIFS(营销场景数据源!$T:$T,营销场景数据源!$C:$C,$B$20,营销场景数据源!$A:$A,BC2) -> 75.45 | BD24: =SUMIFS(营销场景数据源!$T:$T,营销场景数据源!$C:$C,$B$20,营销场景数据源!$A:$A,BD2) -> 0 | BE24: =SUMIFS(营销场景数据源!$T:$T,营销场景数据源!$C:$C,$B$20,营销场景数据源!$A:$A,BE2) -> 0 | ... BY24: =SUMIFS(营销场景数据源!$T:$T,营销场景数据源!$C:$C,$B$20,营销场景数据源!$A:$A,BY2) -> 0 | BZ24: =SUM(CA24:DE24) -> 4362.62 | CA24: =SUMIFS(营销场景数据源!$T:$T,营销场景数据源!$C:$C,$B$20,营销场景数据源!$A:$A,CA2) -> 0 | CB24: =SUMIFS(营销场景数据源!$T:$T,营销场景数据源!$C:$C,$B$20,营销场景数据源!$A:$A,CB2) -> 0 | CC24: =SUMIFS(营销场景数据源!$T:$T,营销场景数据源!$C:$C,$B$20,营销场景数据源!$A:$A,CC2) -> 0 | CD24: =SUMIFS(营销场景数据源!$T:$T,营销场景数据源!$C:$C,$B$20,营销场景数据源!$A:$A,CD2) -> 1413.55 | CE24: =SUMIFS(营销场景数据源!$T:$T,营销场景数据源!$C:$C,$B$20,营销场景数据源!$A:$A,CE2) -> 1301.46 | CF24: =SUMIFS(营销场景数据源!$T:$T,营销场景数据源!$C:$C,$B$20,营销场景数据源!$A:$A,CF2) -> 0 | CG24: =SUMIFS(营销场景数据源!$T:$T,营销场景数据源!$C:$C,$B$20,营销场景数据源!$A:$A,CG2) -> 0 | CH24: =SUMIFS(营销场景数据源!$T:$T,营销场景数据源!$C:$C,$B$20,营销场景数据源!$A:$A,CH2) -> 0 | ... DE24: =SUMIFS(营销场景数据源!$T:$T,营销场景数据源!$C:$C,$B$20,营销场景数据源!$A:$A,DE2) -> 0 | DF24: =SUM(DG24:EJ24) -> 2311.48 | DG24: =SUMIFS(营销场景数据源!$T:$T,营销场景数据源!$C:$C,$B$20,营销场景数据源!$A:$A,DG2) -> 0 | DH24: =SUMIFS(营销场景数据源!$T:$T,营销场景数据源!$C:$C,$B$20,营销场景数据源!$A:$A,DH2) -> 0 | DI24: =SUMIFS(营销场景数据源!$T:$T,营销场景数据源!$C:$C,$B$20,营销场景数据源!$A:$A,DI2) -> 0 | DJ24: =SUMIFS(营销场景数据源!$T:$T,营销场景数据源!$C:$C,$B$20,营销场景数据源!$A:$A,DJ2) -> 0 | DK24: =SUMIFS(营销场景数据源!$T:$T,营销场景数据源!$C:$C,$B$20,营销场景数据源!$A:$A,DK2) -> 0 | DL24: =SUMIFS(营销场景数据源!$T:$T,营销场景数据源!$C:$C,$B$20,营销场景数据源!$A:$A,DL2) -> 0 | DM24: =SUMIFS(营销场景数据源!$T:$T,营销场景数据源!$C:$C,$B$20,营销场景数据源!$A:$A,DM2) -> 0 | DN24: =SUMIFS(营销场景数据源!$T:$T,营销场景数据源!$C:$C,$B$20,营销场景数据源!$A:$A,DN2) -> 0 | ... EJ24: =SUMIFS(营销场景数据源!$T:$T,营销场景数据源!$C:$C,$B$20,营销场景数据源!$A:$A,EJ2) -> 0 | EK24: =SUM(EL24:FP24) -> 11122.7 | EL24: =SUMIFS(营销场景数据源!$T:$T,营销场景数据源!$C:$C,$B$20,营销场景数据源!$A:$A,EL2) -> 0 | EM24: =SUMIFS(营销场景数据源!$T:$T,营销场景数据源!$C:$C,$B$20,营销场景数据源!$A:$A,EM2) -> 151 | EN24: =SUMIFS(营销场景数据源!$T:$T,营销场景数据源!$C:$C,$B$20,营销场景数据源!$A:$A,EN2) -> 0 | EO24: =SUMIFS(营销场景数据源!$T:$T,营销场景数据源!$C:$C,$B$20,营销场景数据源!$A:$A,EO2) -> 0 | EP24: =SUMIFS(营销场景数据源!$T:$T,营销场景数据源!$C:$C,$B$20,营销场景数据源!$A:$A,EP2) -> 0 | EQ24: =SUMIFS(营销场景数据源!$T:$T,营销场景数据源!$C:$C,$B$20,营销场景数据源!$A:$A,EQ2) -> 33.9 | ER24: =SUMIFS(营销场景数据源!$T:$T,营销场景数据源!$C:$C,$B$20,营销场景数据源!$A:$A,ER2) -> 8074 | ES24: =SUMIFS(营销场景数据源!$T:$T,营销场景数据源!$C:$C,$B$20,营销场景数据源!$A:$A,ES2) -> 0 | ... FP24: =SUMIFS(营销场景数据源!$T:$T,营销场景数据源!$C:$C,$B$20,营销场景数据源!$A:$A,FP2) -> 0 | FQ24: =SUM(FR24:GX24) -> 2298.61 | FR24: =SUMIFS(营销场景数据源!$T:$T,营销场景数据源!$C:$C,$B$20,营销场景数据源!$A:$A,FR2) -> 79.8 | FS24: =SUMIFS(营销场景数据源!$T:$T,营销场景数据源!$C:$C,$B$20,营销场景数据源!$A:$A,FS2) -> 75.39 | FT24: =SUMIFS(营销场景数据源!$T:$T,营销场景数据源!$C:$C,$B$20,营销场景数据源!$A:$A,FT2) -> 403.61 | FU24: =SUMIFS(营销场景数据源!$T:$T,营销场景数据源!$C:$C,$B$20,营销场景数据源!$A:$A,FU2) -> 0 | FV24: =SUMIFS(营销场景数据源!$T:$T,营销场景数据源!$C:$C,$B$20,营销场景数据源!$A:$A,FV2) -> 0 | FW24: =SUMIFS(营销场景数据源!$T:$T,营销场景数据源!$C:$C,$B$20,营销场景数据源!$A:$A,FW2) -> 161.58 | FX24: =SUMIFS(营销场景数据源!$T:$T,营销场景数据源!$C:$C,$B$20,营销场景数据源!$A:$A,FX2) -> 242.82 | FY24: =SUMIFS(营销场景数据源!$T:$T,营销场景数据源!$C:$C,$B$20,营销场景数据源!$A:$A,FY2) -> 156.41 | ... GP24: =SUMIFS(营销场景数据源!$T:$T,营销场景数据源!$C:$C,$B$20,营销场景数据源!$A:$A,GP2) -> 0
A25: =A3*A21 -> 0 | C25: 点击单价 | D25: =IFERROR(D20/D21,0) -> 0 | E25: =IFERROR(E20/E21,0) -> 0 | F25: =IFERROR(F20/F21,0) -> 0 | G25: =IFERROR(G20/G21,0) -> 0 | H25: =IFERROR(H20/H21,0) -> 0 | I25: =IFERROR(I20/I21,0) -> 0 | J25: =IFERROR(J20/J21,0) -> 0 | K25: =IFERROR(K20/K21,0) -> 0 | ... GP25: =IFERROR(GP20/GP21,0) -> 0
A26: 实际销售占比 | C26: 加购成本 | D26: =IFERROR(D20/D22,0) -> 0 | E26: =IFERROR(E20/E22,0) -> 0 | F26: =IFERROR(F20/F22,0) -> 0 | G26: =IFERROR(G20/G22,0) -> 0 | H26: =IFERROR(H20/H22,0) -> 0 | I26: =IFERROR(I20/I22,0) -> 0 | J26: =IFERROR(J20/J22,0) -> 0 | K26: =IFERROR(K20/K22,0) -> 0 | ... GP26: =IFERROR(GP20/GP22,0) -> 0
A27: =A5*A23 -> #REF! | C27: ROI | D27: =IFERROR(D24/D20,0) -> 0 | E27: =IFERROR(E24/E20,0) -> 0 | F27: =IFERROR(F24/F20,0) -> 0 | G27: =IFERROR(G24/G20,0) -> 0 | H27: =IFERROR(H24/H20,0) -> 0 | I27: =IFERROR(I24/I20,0) -> 0 | J27: =IFERROR(J24/J20,0) -> 0 | K27: =IFERROR(K24/K20,0) -> 0 | ... GP27: =IFERROR(GP24/GP20,0) -> 0
C28: 费用占比 | D28: =D20/D$130 -> #REF! | E28: =E20/E$130 -> #REF! | F28: =F20/F$130 -> #REF! | G28: =G20/G$130 -> #REF! | H28: =H20/H$130 -> #REF! | I28: =I20/I$130 -> #REF! | J28: =J20/J$130 -> #REF! | K28: =K20/K$130 -> #REF! | ... GP28: =GP20/GP$130 -> #DIV/0!
B29: 人群推广 | C29: 花费 | D29: =SUM(E29:P29) -> #REF! | E29: =#REF! -> #REF! | F29: =#REF! -> #REF! | G29: =#REF! -> #REF! | H29: =#REF! -> #REF! | I29: =#REF! -> #REF! | J29: =#REF! -> #REF! | K29: =#REF! -> #REF! | L29: =#REF! -> #REF! | ... P29: =#REF! -> #REF! | Q29: =SUM(R29:AV29) -> 3304.75 | R29: =SUMIFS(营销场景数据源!$H:$H,营销场景数据源!$C:$C,$B$29,营销场景数据源!$A:$A,R2) -> 99.76 | S29: =SUMIFS(营销场景数据源!$H:$H,营销场景数据源!$C:$C,$B$29,营销场景数据源!$A:$A,S2) -> 87.67 | T29: =SUMIFS(营销场景数据源!$H:$H,营销场景数据源!$C:$C,$B$29,营销场景数据源!$A:$A,T2) -> 138.13 | U29: =SUMIFS(营销场景数据源!$H:$H,营销场景数据源!$C:$C,$B$29,营销场景数据源!$A:$A,U2) -> 187.34 | V29: =SUMIFS(营销场景数据源!$H:$H,营销场景数据源!$C:$C,$B$29,营销场景数据源!$A:$A,V2) -> 132.55 | W29: =SUMIFS(营销场景数据源!$H:$H,营销场景数据源!$C:$C,$B$29,营销场景数据源!$A:$A,W2) -> 151.03 | X29: =SUMIFS(营销场景数据源!$H:$H,营销场景数据源!$C:$C,$B$29,营销场景数据源!$A:$A,X2) -> 139.72 | Y29: =SUMIFS(营销场景数据源!$H:$H,营销场景数据源!$C:$C,$B$29,营销场景数据源!$A:$A,Y2) -> 131.9 | ... AV29: =SUMIFS(营销场景数据源!$H:$H,营销场景数据源!$C:$C,$B$29,营销场景数据源!$A:$A,AV2) -> 51.47 | AW29: =SUM(AX29:BY29) -> 352.13 | AX29: =SUMIFS(营销场景数据源!$H:$H,营销场景数据源!$C:$C,$B$29,营销场景数据源!$A:$A,AX2) -> 56.2 | AY29: =SUMIFS(营销场景数据源!$H:$H,营销场景数据源!$C:$C,$B$29,营销场景数据源!$A:$A,AY2) -> 60.23 | AZ29: =SUMIFS(营销场景数据源!$H:$H,营销场景数据源!$C:$C,$B$29,营销场景数据源!$A:$A,AZ2) -> 37.32 | BA29: =SUMIFS(营销场景数据源!$H:$H,营销场景数据源!$C:$C,$B$29,营销场景数据源!$A:$A,BA2) -> 31.01 | BB29: =SUMIFS(营销场景数据源!$H:$H,营销场景数据源!$C:$C,$B$29,营销场景数据源!$A:$A,BB2) -> 42.08 | BC29: =SUMIFS(营销场景数据源!$H:$H,营销场景数据源!$C:$C,$B$29,营销场景数据源!$A:$A,BC2) -> 20.9 | BD29: =SUMIFS(营销场景数据源!$H:$H,营销场景数据源!$C:$C,$B$29,营销场景数据源!$A:$A,BD2) -> 32.71 | BE29: =SUMIFS(营销场景数据源!$H:$H,营销场景数据源!$C:$C,$B$29,营销场景数据源!$A:$A,BE2) -> 35 | ... BY29: =SUMIFS(营销场景数据源!$H:$H,营销场景数据源!$C:$C,$B$29,营销场景数据源!$A:$A,BY2) -> 0 | BZ29: =SUM(CA29:DE29) -> 0 | CA29: =SUMIFS(营销场景数据源!$H:$H,营销场景数据源!$C:$C,$B$29,营销场景数据源!$A:$A,CA2) -> 0 | CB29: =SUMIFS(营销场景数据源!$H:$H,营销场景数据源!$C:$C,$B$29,营销场景数据源!$A:$A,CB2) -> 0 | CC29: =SUMIFS(营销场景数据源!$H:$H,营销场景数据源!$C:$C,$B$29,营销场景数据源!$A:$A,CC2) -> 0 | CD29: =SUMIFS(营销场景数据源!$H:$H,营销场景数据源!$C:$C,$B$29,营销场景数据源!$A:$A,CD2) -> 0 | CE29: =SUMIFS(营销场景数据源!$H:$H,营销场景数据源!$C:$C,$B$29,营销场景数据源!$A:$A,CE2) -> 0 | CF29: =SUMIFS(营销场景数据源!$H:$H,营销场景数据源!$C:$C,$B$29,营销场景数据源!$A:$A,CF2) -> 0 | CG29: =SUMIFS(营销场景数据源!$H:$H,营销场景数据源!$C:$C,$B$29,营销场景数据源!$A:$A,CG2) -> 0 | CH29: =SUMIFS(营销场景数据源!$H:$H,营销场景数据源!$C:$C,$B$29,营销场景数据源!$A:$A,CH2) -> 0 | ... DE29: =SUMIFS(营销场景数据源!$H:$H,营销场景数据源!$C:$C,$B$29,营销场景数据源!$A:$A,DE2) -> 0 | DF29: =SUM(DG29:EJ29) -> 2308.45 | DG29: =SUMIFS(营销场景数据源!$H:$H,营销场景数据源!$C:$C,$B$29,营销场景数据源!$A:$A,DG2) -> 0 | DH29: =SUMIFS(营销场景数据源!$H:$H,营销场景数据源!$C:$C,$B$29,营销场景数据源!$A:$A,DH2) -> 0 | DI29: =SUMIFS(营销场景数据源!$H:$H,营销场景数据源!$C:$C,$B$29,营销场景数据源!$A:$A,DI2) -> 49.84 | DJ29: =SUMIFS(营销场景数据源!$H:$H,营销场景数据源!$C:$C,$B$29,营销场景数据源!$A:$A,DJ2) -> 50 | DK29: =SUMIFS(营销场景数据源!$H:$H,营销场景数据源!$C:$C,$B$29,营销场景数据源!$A:$A,DK2) -> 108 | DL29: =SUMIFS(营销场景数据源!$H:$H,营销场景数据源!$C:$C,$B$29,营销场景数据源!$A:$A,DL2) -> 50 | DM29: =SUMIFS(营销场景数据源!$H:$H,营销场景数据源!$C:$C,$B$29,营销场景数据源!$A:$A,DM2) -> 100 | DN29: =SUMIFS(营销场景数据源!$H:$H,营销场景数据源!$C:$C,$B$29,营销场景数据源!$A:$A,DN2) -> 211.61 | ... EJ29: =SUMIFS(营销场景数据源!$H:$H,营销场景数据源!$C:$C,$B$29,营销场景数据源!$A:$A,EJ2) -> 70.03 | EK29: =SUM(EL29:FP29) -> 2337.35 | EL29: =SUMIFS(营销场景数据源!$H:$H,营销场景数据源!$C:$C,$B$29,营销场景数据源!$A:$A,EL2) -> 90.15 | EM29: =SUMIFS(营销场景数据源!$H:$H,营销场景数据源!$C:$C,$B$29,营销场景数据源!$A:$A,EM2) -> 83.83 | EN29: =SUMIFS(营销场景数据源!$H:$H,营销场景数据源!$C:$C,$B$29,营销场景数据源!$A:$A,EN2) -> 100.4 | EO29: =SUMIFS(营销场景数据源!$H:$H,营销场景数据源!$C:$C,$B$29,营销场景数据源!$A:$A,EO2) -> 90.27 | EP29: =SUMIFS(营销场景数据源!$H:$H,营销场景数据源!$C:$C,$B$29,营销场景数据源!$A:$A,EP2) -> 101.66 | EQ29: =SUMIFS(营销场景数据源!$H:$H,营销场景数据源!$C:$C,$B$29,营销场景数据源!$A:$A,EQ2) -> 77.37 | ER29: =SUMIFS(营销场景数据源!$H:$H,营销场景数据源!$C:$C,$B$29,营销场景数据源!$A:$A,ER2) -> 72.05 | ES29: =SUMIFS(营销场景数据源!$H:$H,营销场景数据源!$C:$C,$B$29,营销场景数据源!$A:$A,ES2) -> 94.72 | ... FP29: =SUMIFS(营销场景数据源!$H:$H,营销场景数据源!$C:$C,$B$29,营销场景数据源!$A:$A,FP2) -> 79.89 | FQ29: =SUM(FR29:GX29) -> 1261.23 | FR29: =SUMIFS(营销场景数据源!$H:$H,营销场景数据源!$C:$C,$B$29,营销场景数据源!$A:$A,FR2) -> 54.7 | FS29: =SUMIFS(营销场景数据源!$H:$H,营销场景数据源!$C:$C,$B$29,营销场景数据源!$A:$A,FS2) -> 52.78 | FT29: =SUMIFS(营销场景数据源!$H:$H,营销场景数据源!$C:$C,$B$29,营销场景数据源!$A:$A,FT2) -> 40.39 | FU29: =SUMIFS(营销场景数据源!$H:$H,营销场景数据源!$C:$C,$B$29,营销场景数据源!$A:$A,FU2) -> 54.26 | FV29: =SUMIFS(营销场景数据源!$H:$H,营销场景数据源!$C:$C,$B$29,营销场景数据源!$A:$A,FV2) -> 29.89 | FW29: =SUMIFS(营销场景数据源!$H:$H,营销场景数据源!$C:$C,$B$29,营销场景数据源!$A:$A,FW2) -> 73.06 | FX29: =SUMIFS(营销场景数据源!$H:$H,营销场景数据源!$C:$C,$B$29,营销场景数据源!$A:$A,FX2) -> 83.17 | FY29: =SUMIFS(营销场景数据源!$H:$H,营销场景数据源!$C:$C,$B$29,营销场景数据源!$A:$A,FY2) -> 68.12 | ... GP29: =SUMIFS(营销场景数据源!$H:$H,营销场景数据源!$C:$C,$B$29,营销场景数据源!$A:$A,GP2) -> 0
C30: 点击量 | D30: =SUM(E30:P30) -> #REF! | E30: =#REF! -> #REF! | F30: =#REF! -> #REF! | G30: =#REF! -> #REF! | H30: =#REF! -> #REF! | I30: =#REF! -> #REF! | J30: =#REF! -> #REF! | K30: =#REF! -> #REF! | L30: =#REF! -> #REF! | ... P30: =#REF! -> #REF! | Q30: =SUM(R30:AV30) -> 1840 | R30: =SUMIFS(营销场景数据源!$G:$G,营销场景数据源!$C:$C,$B$29,营销场景数据源!$A:$A,R2) -> 78 | S30: =SUMIFS(营销场景数据源!$G:$G,营销场景数据源!$C:$C,$B$29,营销场景数据源!$A:$A,S2) -> 95 | T30: =SUMIFS(营销场景数据源!$G:$G,营销场景数据源!$C:$C,$B$29,营销场景数据源!$A:$A,T2) -> 127 | U30: =SUMIFS(营销场景数据源!$G:$G,营销场景数据源!$C:$C,$B$29,营销场景数据源!$A:$A,U2) -> 127 | V30: =SUMIFS(营销场景数据源!$G:$G,营销场景数据源!$C:$C,$B$29,营销场景数据源!$A:$A,V2) -> 112 | W30: =SUMIFS(营销场景数据源!$G:$G,营销场景数据源!$C:$C,$B$29,营销场景数据源!$A:$A,W2) -> 73 | X30: =SUMIFS(营销场景数据源!$G:$G,营销场景数据源!$C:$C,$B$29,营销场景数据源!$A:$A,X2) -> 90 | Y30: =SUMIFS(营销场景数据源!$G:$G,营销场景数据源!$C:$C,$B$29,营销场景数据源!$A:$A,Y2) -> 64 | ... AV30: =SUMIFS(营销场景数据源!$G:$G,营销场景数据源!$C:$C,$B$29,营销场景数据源!$A:$A,AV2) -> 25 | AW30: =SUM(AX30:BY30) -> 154 | AX30: =SUMIFS(营销场景数据源!$G:$G,营销场景数据源!$C:$C,$B$29,营销场景数据源!$A:$A,AX2) -> 22 | AY30: =SUMIFS(营销场景数据源!$G:$G,营销场景数据源!$C:$C,$B$29,营销场景数据源!$A:$A,AY2) -> 28 | AZ30: =SUMIFS(营销场景数据源!$G:$G,营销场景数据源!$C:$C,$B$29,营销场景数据源!$A:$A,AZ2) -> 15 | BA30: =SUMIFS(营销场景数据源!$G:$G,营销场景数据源!$C:$C,$B$29,营销场景数据源!$A:$A,BA2) -> 11 | BB30: =SUMIFS(营销场景数据源!$G:$G,营销场景数据源!$C:$C,$B$29,营销场景数据源!$A:$A,BB2) -> 15 | BC30: =SUMIFS(营销场景数据源!$G:$G,营销场景数据源!$C:$C,$B$29,营销场景数据源!$A:$A,BC2) -> 11 | BD30: =SUMIFS(营销场景数据源!$G:$G,营销场景数据源!$C:$C,$B$29,营销场景数据源!$A:$A,BD2) -> 19 | BE30: =SUMIFS(营销场景数据源!$G:$G,营销场景数据源!$C:$C,$B$29,营销场景数据源!$A:$A,BE2) -> 19 | ... BY30: =SUMIFS(营销场景数据源!$G:$G,营销场景数据源!$C:$C,$B$29,营销场景数据源!$A:$A,BY2) -> 0 | BZ30: =SUM(CA30:DE30) -> 0 | CA30: =SUMIFS(营销场景数据源!$G:$G,营销场景数据源!$C:$C,$B$29,营销场景数据源!$A:$A,CA2) -> 0 | CB30: =SUMIFS(营销场景数据源!$G:$G,营销场景数据源!$C:$C,$B$29,营销场景数据源!$A:$A,CB2) -> 0 | CC30: =SUMIFS(营销场景数据源!$G:$G,营销场景数据源!$C:$C,$B$29,营销场景数据源!$A:$A,CC2) -> 0 | CD30: =SUMIFS(营销场景数据源!$G:$G,营销场景数据源!$C:$C,$B$29,营销场景数据源!$A:$A,CD2) -> 0 | CE30: =SUMIFS(营销场景数据源!$G:$G,营销场景数据源!$C:$C,$B$29,营销场景数据源!$A:$A,CE2) -> 0 | CF30: =SUMIFS(营销场景数据源!$G:$G,营销场景数据源!$C:$C,$B$29,营销场景数据源!$A:$A,CF2) -> 0 | CG30: =SUMIFS(营销场景数据源!$G:$G,营销场景数据源!$C:$C,$B$29,营销场景数据源!$A:$A,CG2) -> 0 | CH30: =SUMIFS(营销场景数据源!$G:$G,营销场景数据源!$C:$C,$B$29,营销场景数据源!$A:$A,CH2) -> 0 | ... DE30: =SUMIFS(营销场景数据源!$G:$G,营销场景数据源!$C:$C,$B$29,营销场景数据源!$A:$A,DE2) -> 0 | DF30: =SUM(DG30:EJ30) -> 3735 | DG30: =SUMIFS(营销场景数据源!$G:$G,营销场景数据源!$C:$C,$B$29,营销场景数据源!$A:$A,DG2) -> 0 | DH30: =SUMIFS(营销场景数据源!$G:$G,营销场景数据源!$C:$C,$B$29,营销场景数据源!$A:$A,DH2) -> 0 | DI30: =SUMIFS(营销场景数据源!$G:$G,营销场景数据源!$C:$C,$B$29,营销场景数据源!$A:$A,DI2) -> 40 | DJ30: =SUMIFS(营销场景数据源!$G:$G,营销场景数据源!$C:$C,$B$29,营销场景数据源!$A:$A,DJ2) -> 27 | DK30: =SUMIFS(营销场景数据源!$G:$G,营销场景数据源!$C:$C,$B$29,营销场景数据源!$A:$A,DK2) -> 75 | DL30: =SUMIFS(营销场景数据源!$G:$G,营销场景数据源!$C:$C,$B$29,营销场景数据源!$A:$A,DL2) -> 23 | DM30: =SUMIFS(营销场景数据源!$G:$G,营销场景数据源!$C:$C,$B$29,营销场景数据源!$A:$A,DM2) -> 64 | DN30: =SUMIFS(营销场景数据源!$G:$G,营销场景数据源!$C:$C,$B$29,营销场景数据源!$A:$A,DN2) -> 148 | ... EJ30: =SUMIFS(营销场景数据源!$G:$G,营销场景数据源!$C:$C,$B$29,营销场景数据源!$A:$A,EJ2) -> 221 | EK30: =SUM(EL30:FP30) -> 6320 | EL30: =SUMIFS(营销场景数据源!$G:$G,营销场景数据源!$C:$C,$B$29,营销场景数据源!$A:$A,EL2) -> 287 | EM30: =SUMIFS(营销场景数据源!$G:$G,营销场景数据源!$C:$C,$B$29,营销场景数据源!$A:$A,EM2) -> 268 | EN30: =SUMIFS(营销场景数据源!$G:$G,营销场景数据源!$C:$C,$B$29,营销场景数据源!$A:$A,EN2) -> 290 | EO30: =SUMIFS(营销场景数据源!$G:$G,营销场景数据源!$C:$C,$B$29,营销场景数据源!$A:$A,EO2) -> 277 | EP30: =SUMIFS(营销场景数据源!$G:$G,营销场景数据源!$C:$C,$B$29,营销场景数据源!$A:$A,EP2) -> 300 | EQ30: =SUMIFS(营销场景数据源!$G:$G,营销场景数据源!$C:$C,$B$29,营销场景数据源!$A:$A,EQ2) -> 239 | ER30: =SUMIFS(营销场景数据源!$G:$G,营销场景数据源!$C:$C,$B$29,营销场景数据源!$A:$A,ER2) -> 214 | ES30: =SUMIFS(营销场景数据源!$G:$G,营销场景数据源!$C:$C,$B$29,营销场景数据源!$A:$A,ES2) -> 282 | ... FP30: =SUMIFS(营销场景数据源!$G:$G,营销场景数据源!$C:$C,$B$29,营销场景数据源!$A:$A,FP2) -> 196 | FQ30: =SUM(FR30:GX30) -> 2797 | FR30: =SUMIFS(营销场景数据源!$G:$G,营销场景数据源!$C:$C,$B$29,营销场景数据源!$A:$A,FR2) -> 111 | FS30: =SUMIFS(营销场景数据源!$G:$G,营销场景数据源!$C:$C,$B$29,营销场景数据源!$A:$A,FS2) -> 90 | FT30: =SUMIFS(营销场景数据源!$G:$G,营销场景数据源!$C:$C,$B$29,营销场景数据源!$A:$A,FT2) -> 78 | FU30: =SUMIFS(营销场景数据源!$G:$G,营销场景数据源!$C:$C,$B$29,营销场景数据源!$A:$A,FU2) -> 96 | FV30: =SUMIFS(营销场景数据源!$G:$G,营销场景数据源!$C:$C,$B$29,营销场景数据源!$A:$A,FV2) -> 52 | FW30: =SUMIFS(营销场景数据源!$G:$G,营销场景数据源!$C:$C,$B$29,营销场景数据源!$A:$A,FW2) -> 159 | FX30: =SUMIFS(营销场景数据源!$G:$G,营销场景数据源!$C:$C,$B$29,营销场景数据源!$A:$A,FX2) -> 213 | FY30: =SUMIFS(营销场景数据源!$G:$G,营销场景数据源!$C:$C,$B$29,营销场景数据源!$A:$A,FY2) -> 147 | ... GP30: =SUMIFS(营销场景数据源!$G:$G,营销场景数据源!$C:$C,$B$29,营销场景数据源!$A:$A,GP2) -> 0
